Workbook

Sheet __FDSCACHE__
B1: This sheet contains FactSet XML data for use with this workbook's =FDS codes. Modifying the worksheet's contents may damage the workbook's =FDS functionality.

Sheet 통합명세부
A1: 순번 | B1: 국내/해외 | C1: 기준일자 | D1: 자산구분 | E1: 운용역 | F1: 펀드 | G1: 펀드명 | H1: 구분 | I1: 발행기관명 | J1: 종목 | K1: TICKER | L1: 종목명 | M1: 주수/계약수/액면 | N1: 취득가 | O1: 가격/종가 | P1: 평가손익 | Q1: 장부평가액 | R1: 시가평가액 | S1: 경과이자(선수) | T1: 누적이자 | U1: 순자산 | V1: 기준가격 | W1: 발행일 | X1: 상환일 | Y1: 이자구분 | Z1: 이자지급일 | AA1: 반영% | AB1: 표면% | AC1: 적용% | AD1: 매입% | AE1: 수익률 | AF1: 수탁사 | AG1: 듀레이션 | AH1: 신용등급 | AI1: 종목비중 | AJ1: 순자산비중 | AK1: Unnamed: 36
A2: 1 | B2: 국내 | C2: 45348 | D2: 주식 | E2: 정지영 | F2: 03V94 | G2: 한국투자글로벌채권솔루션증권모투자신탁(채권-재간접형) | H2: ETF(거래소)(채권) | I2: KINDEX 단기자금 증권 | J2: KR7190620005 | L2: ACE 단기통안채 | M2: 4000 | N2: 404586533 | O2: 100860 | P2: -1146533 | Q2: 404586533 | R2: 403440000 | S2: 0 | T2: 0 | U2: 14251350122 | V2: 906.66 | AA2: 0 | AB2: 0 | AC2: 0 | AD2: 0 | AE2: -0.28 | AF2: 신한은행 | AG2: 0 | AI2: 2.82 | AJ2: 2.83
A3: 2 | B3: 국내 | C3: 45348 | D3: 주식 | E3: 정지영 | F3: 03V94 | G3: 한국투자글로벌채권솔루션증권모투자신탁(채권-재간접형) | H3: ETF(거래소)(채권) | I3: 한국투자KINDEXKIS종합채권(AA- | J3: KR7356540005 | L3: ACE 종합채권(AA-이상)KIS액티브 | M3: 466 | N3: 45188853 | O3: 100030 | P3: 1425127 | Q3: 45188853 | R3: 46613980 | S3: 0 | T3: 0 | U3: 14251350122 | V3: 906.66 | AA3: 0 | AB3: 0 | AC3: 0 | AD3: 0 | AE3: 3.15 | AF3: 신한은행 | AG3: 0 | AI3: 0.33 | AJ3: 0.33
A4: 3 | B4: 국내 | C4: 45348 | D4: 현금 | E4: 정지영 | F4: 03V94 | G4: 한국투자글로벌채권솔루션증권모투자신탁(채권-재간접형) | H4: 보통예금 | I4: 공통 | J4: KR9999990000 | L4: 예금 | M4: 115195321 | N4: 115195321 | O4: 0 | P4: 0 | Q4: 115606468 | R4: 115606468 | S4: 0 | T4: 411147 | U4: 14251350122 | V4: 906.66 | Y4: 만기일시 | AA4: 2.97919 | AB4: 2.99 | AC4: 0 | AD4: 2.99 | AE4: 0 | AF4: 신한은행 | AG4: 0 | AI4: 0.81 | AJ4: 0.81
A5: 4 | B5: 국내 | C5: 45348 | D5: 기타자산 | E5: 정지영 | F5: 03V95 | G5: 한국투자글로벌주식솔루션증권모투자신탁(주식-재간접형) | H5: 계정코드 | J5: 1792100 | L5: 미수외국납부원천세환급액 | M5: 0 | N5: 0 | O5: 0 | P5: 0 | Q5: 16165030 | R5: 16165030 | S5: 0 | T5: 0 | U5: 5396698880 | V5: 1293.33 | AA5: 0 | AB5: 0 | AC5: 0 | AD5: 0 | AE5: 0 | AF5: 신한은행 | AG5: 0 | AI5: 0.3 | AJ5: 0.3
A6: 5 | B6: 국내 | C6: 45348 | D6: 현금 | E6: 정지영 | F6: 03V95 | G6: 한국투자글로벌주식솔루션증권모투자신탁(주식-재간접형) | H6: 보통예금 | I6: 공통 | J6: KR9999990000 | L6: 예금 | M6: 48609544 | N6: 48609544 | O6: 0 | P6: 0 | Q6: 48806859 | R6: 48806859 | S6: 0 | T6: 197315 | U6: 5396698880 | V6: 1293.33 | Y6: 만기일시 | AA6: 2.97792 | AB6: 2.99 | AC6: 0 | AD6: 2.99 | AE6: 0 | AF6: 신한은행 | AG6: 0 | AI6: 0.9 | AJ6: 0.9
A7: 6 | B7: 국내 | C7: 45348 | D7: 선물매도 | E7: 민상구 | F7: 05C02 | G7: 한국투자TDF알아서증권투자신탁(채권혼합-재간접형)(모) | H7: 달러선물 | I7: N/A | J7: KR4175V30009 | L7: 미국달러 F 202403 | M7: 760 | N7: 10098880000 | O7: 1330.5 | P7: -12920000 | Q7: 0 | R7: 10111800000 | S7: 0 | T7: 0 | U7: 177518001444 | V7: 1267.23 | W7: 44271 | X7: 45369 | Y7: N/A | Z7: 0000-01-01 | AA7: 0 | AB7: 0 | AC7: 0 | AD7: 0 | AE7: 0 | AF7: 우리은행 | AG7: 0 | AH7: N/A | AI7: 5.26 | AJ7: 5.7
A8: 7 | B8: 국내 | C8: 45348 | D8: 선물매도 | E8: 민상구 | F8: 05C02 | G8: 한국투자TDF알아서증권투자신탁(채권혼합-재간접형)(모) | H8: 달러선물 | I8: N/A | J8: KR4175V30009 | L8: 미국달러 F 202403 | M8: 230 | N8: 3056240000 | O8: 1330.5 | P8: -3910000 | Q8: 0 | R8: 3060150000 | S8: 0 | T8: 0 | U8: 177518001444 | V8: 1267.23 | W8: 44271 | X8: 45369 | Y8: N/A | Z8: 0000-01-01 | AA8: 0 | AB8: 0 | AC8: 0 | AD8: 0 | AE8: 0 | AF8: 우리은행 | AG8: 0 | AH8: N/A | AI8: 1.59 | AJ8: 1.72
A9: 8 | B9: 국내 | C9: 45348 | D9: 주식 | E9: 민상구 | F9: 05C02 | G9: 한국투자TDF알아서증권투자신탁(채권혼합-재간접형)(모) | H9: ETF(거래소)(채권) | I9: 한국투자KINDEXKIS종합채권(AA- | J9: KR7356540005 | L9: ACE 종합채권(AA-이상)KIS액티브 | M9: 112474 | N9: 10439078724 | O9: 100030 | P9: 811695496 | Q9: 10439078724 | R9: 11250774220 | S9: 0 | T9: 0 | U9: 177518001444 | V9: 1267.23 | AA9: 0 | AB9: 0 | AC9: 0 | AD9: 0 | AE9: 7.78 | AF9: 우리은행 | AG9: 0 | AI9: 5.86 | AJ9: 6.34
A10: 9 | B10: 국내 | C10: 45348 | D10: 현금 | E10: 민상구 | F10: 05C02 | G10: 한국투자TDF알아서증권투자신탁(채권혼합-재간접형)(모) | H10: 보통예금 | I10: 공통 | J10: KR9999990000 | L10: 예금 | M10: 2806116755 | N10: 2806116755 | O10: 0 | P10: 0 | Q10: 2810933720 | R10: 2810933720 | S10: 0 | T10: 4816965 | U10: 177518001444 | V10: 1267.23 | Y10: 만기일시 | AA10: 2.98488 | AB10: 2.99 | AC10: 0 | AD10: 2.99 | AE10: 0 | AF10: 우리은행 | AG10: 0 | AI10: 1.46 | AJ10: 1.58
A11: 10 | B11: 국내 | C11: 45348 | D11: 현금 | E11: 민상구 | F11: 05C02 | G11: 한국투자TDF알아서증권투자신탁(채권혼합-재간접형)(모) | H11: 콜론 | I11: 한국증권금융 | J11: KR9E22680009 | L11: 증권금융(콜론) | M11: 1586980000 | N11: 1586980000 | O11: 0 | P11: 0 | Q11: 1587131307 | R11: 1587131307 | S11: 0 | T11: 151307 | U11: 177518001444 | V11: 1267.23 | W11: 45348 | X11: 45349 | Y11: 만기일시 | AA11: 3.47968 | AB11: 3.48 | AC11: 0 | AD11: 3.48 | AE11: 0 | AF11: 우리은행 | AG11: 0 | AI11: 0.83 | AJ11: 0.89
A12: 11 | B12: 국내 | C12: 45348 | D12: 현금 | E12: 민상구 | F12: 05C02 | G12: 한국투자TDF알아서증권투자신탁(채권혼합-재간접형)(모) | H12: 콜론 | I12: 삼성증권 | J12: KR9E22680023 | L12: 삼성증권(콜론) | M12: 1102640000 | N12: 1102640000 | O12: 0 | P12: 0 | Q12: 1102750868 | R12: 1102750868 | S12: 0 | T12: 110868 | U12: 177518001444 | V12: 1267.23 | W12: 45348 | X12: 45349 | Y12: 만기일시 | AA12: 3.66962 | AB12: 3.67 | AC12: 0 | AD12: 3.67 | AE12: 0 | AF12: 우리은행 | AG12: 0 | AI12: 0.57 | AJ12: 0.62
A13: 12 | B13: 국내 | C13: 45348 | D13: 현금 | E13: 민상구 | F13: 05C02 | G13: 한국투자TDF알아서증권투자신탁(채권혼합-재간접형)(모) | H13: 현금위탁증거금 | I13: 신한투자증권 | J13: 000002000000 | L13: 신한금융투자(증거금) | M13: 146271140 | N13: 146271140 | O13: 0 | P13: 0 | Q13: 146271140 | R13: 146271140 | S13: 0 | T13: 0 | U13: 177518001444 | V13: 1267.23 | Y13: 만기일시 | AA13: 0 | AB13: 0 | AC13: 0 | AD13: 0 | AE13: 0 | AF13: 우리은행 | AG13: 0 | AI13: 0.08 | AJ13: 0.08
A14: 13 | B14: 국내 | C14: 45348 | D14: 현금 | E14: 민상구 | F14: 05C02 | G14: 한국투자TDF알아서증권투자신탁(채권혼합-재간접형)(모) | H14: 현금위탁증거금 | I14: 한국투자증권 | J14: 000003000000 | L14: 한국투자증권(증거금) | M14: 470375400 | N14: 470375400 | O14: 0 | P14: 0 | Q14: 470375400 | R14: 470375400 | S14: 0 | T14: 0 | U14: 177518001444 | V14: 1267.23 | Y14: 만기일시 | AA14: 0 | AB14: 0 | AC14: 0 | AD14: 0 | AE14: 0 | AF14: 우리은행 | AG14: 0 | AI14: 0.25 | AJ14: 0.26
A15: 14 | B15: 국내 | C15: 45348 | D15: 기타자산 | E15: 민상구 | F15: 05C03 | G15: 한국투자TDF알아서증권투자신탁(채권혼합-재간접형)(A) | H15: 계정코드 | J15: 1711700 | L15: 집합투자증권매도미수금 | M15: 0 | N15: 0 | O15: 0 | P15: 0 | Q15: 0 | R15: 0 | S15: 0 | T15: 0 | U15: 1220059502 | V15: 1243 | AA15: 0 | AB15: 0 | AC15: 0 | AD15: 0 | AE15: 0 | AF15: 우리은행 | AG15: 0 | AI15: 0 | AJ15: 0
A16: 15 | B16: 국내 | C16: 45348 | D16: 집합증권 | E16: 민상구 | F16: 05C03 | G16: 한국투자TDF알아서증권투자신탁(채권혼합-재간접형)(A) | H16: 종류형모펀드 | I16: 한국투자신탁운용 | J16: 032280005C02 | L16: 한국투자TDF알아서증권투자신탁(채권혼합-재간접형)(모) | M16: 962835843 | N16: 1234647262 | O16: 1267.23 | P16: -14512053 | Q16: 1220135209 | R16: 1220135209 | S16: 0 | T16: 0 | U16: 1220059502 | V16: 1243 | W16: 42788 | X16: 0000-01-01 | Y16: N/A | Z16: 45343 | AA16: 0 | AB16: 0 | AC16: 0 | AD16: 0 | AE16: 0 | AF16: 우리은행 | AG16: 0 | AH16: N/A | AI16: 100 | AJ16: 100.01
A17: 16 | B17: 국내 | C17: 45348 | D17: 현금 | E17: 민상구 | F17: 05C03 | G17: 한국투자TDF알아서증권투자신탁(채권혼합-재간접형)(A) | H17: 보통예금 | I17: 공통 | J17: KR9999990000 | L17: 예금 | M17: 0 | N17: 0 | O17: 0 | P17: 0 | Q17: 0 | R17: 0 | S17: 0 | T17: 0 | U17: 1220059502 | V17: 1243 | Y17: 만기일시 | AA17: 0 | AB17: 2.99 | AC17: 0 | AD17: 2.99 | AE17: 0 | AF17: 우리은행 | AG17: 0 | AI17: 0 | AJ17: 0
A18: 17 | B18: 국내 | C18: 45348 | D18: 기타자산 | E18: 민상구 | F18: 05C04 | G18: 한국투자TDF알아서증권투자신탁(채권혼합-재간접형)(A-e) | H18: 계정코드 | J18: 1711700 | L18: 집합투자증권매도미수금 | M18: 0 | N18: 0 | O18: 0 | P18: 0 | Q18: 5322875 | R18: 5322875 | S18: 0 | T18: 0 | U18: 540990684 | V18: 1200.74 | AA18: 0 | AB18: 0 | AC18: 0 | AD18: 0 | AE18: 0 | AF18: 우리은행 | AG18: 0 | AI18: 0.97 | AJ18: 0.98
A19: 18 | B19: 국내 | C19: 45348 | D19: 집합증권 | E19: 민상구 | F19: 05C04 | G19: 한국투자TDF알아서증권투자신탁(채권혼합-재간접형)(A-e) | H19: 종류형모펀드 | I19: 한국투자신탁운용 | J19: 032280005C02 | L19: 한국투자TDF알아서증권투자신탁(채권혼합-재간접형)(모) | M19: 426928443 | N19: 534907748 | O19: 1267.23 | P19: 6109113 | Q19: 541016861 | R19: 541016861 | S19: 0 | T19: 0 | U19: 540990684 | V19: 1200.74 | W19: 42788 | X19: 0000-01-01 | Y19: N/A | Z19: 45343 | AA19: 0 | AB19: 0 | AC19: 0 | AD19: 0 | AE19: 0 | AF19: 우리은행 | AG19: 0 | AH19: N/A | AI19: 99.03 | AJ19: 100
A20: 19 | B20: 국내 | C20: 45348 | D20: 현금 | E20: 민상구 | F20: 05C04 | G20: 한국투자TDF알아서증권투자신탁(채권혼합-재간접형)(A-e) | H20: 보통예금 | I20: 공통 | J20: KR9999990000 | L20: 예금 | M20: 0 | N20: 0 | O20: 0 | P20: 0 | Q20: 0 | R20: 0 | S20: 0 | T20: 0 | U20: 540990684 | V20: 1200.74 | Y20: 만기일시 | AA20: 0 | AB20: 2.99 | AC20: 0 | AD20: 2.99 | AE20: 0 | AF20: 우리은행 | AG20: 0 | AI20: 0 | AJ20: 0
A21: 20 | B21: 국내 | C21: 45348 | D21: 집합증권 | E21: 민상구 | F21: 05C05 | G21: 한국투자TDF알아서증권투자신탁(채권혼합-재간접형)(C) | H21: 종류형모펀드 | I21: 한국투자신탁운용 | J21: 032280005C02 | L21: 한국투자TDF알아서증권투자신탁(채권혼합-재간접형)(모) | M21: 395631498 | N21: 508674973 | O21: 1267.23 | P21: -7318564 | Q21: 501356409 | R21: 501356409 | S21: 0 | T21: 0 | U21: 501302206 | V21: 1173.67 | W21: 42788 | X21: 0000-01-01 | Y21: N/A | Z21: 45343 | AA21: 0 | AB21: 0 | AC21: 0 | AD21: 0 | AE21: 0 | AF21: 우리은행 | AG21: 0 | AH21: N/A | AI21: 100 | AJ21: 100.01
A22: 21 | B22: 국내 | C22: 45348 | D22: 현금 | E22: 민상구 | F22: 05C05 | G22: 한국투자TDF알아서증권투자신탁(채권혼합-재간접형)(C) | H22: 보통예금 | I22: 공통 | J22: KR9999990000 | L22: 예금 | M22: 0 | N22: 0 | O22: 0 | P22: 0 | Q22: 0 | R22: 0 | S22: 0 | T22: 0 | U22: 501302206 | V22: 1173.67 | Y22: 만기일시 | AA22: 0 | AB22: 2.99 | AC22: 0 | AD22: 2.99 | AE22: 0 | AF22: 우리은행 | AG22: 0 | AI22: 0 | AJ22: 0
A23: 22 | B23: 국내 | C23: 45348 | D23: 집합증권 | E23: 민상구 | F23: 05C06 | G23: 한국투자TDF알아서증권투자신탁(채권혼합-재간접형)(C-e) | H23: 종류형모펀드 | I23: 한국투자신탁운용 | J23: 032280005C02 | L23: 한국투자TDF알아서증권투자신탁(채권혼합-재간접형)(모) | M23: 310918297 | N23: 394318627 | O23: 1267.23 | P23: -313393 | Q23: 394005234 | R23: 394005234 | S23: 0 | T23: 0 | U23: 393977063 | V23: 1202.75 | W23: 42788 | X23: 0000-01-01 | Y23: N/A | Z23: 45343 | AA23: 0 | AB23: 0 | AC23: 0 | AD23: 0 | AE23: 0 | AF23: 우리은행 | AG23: 0 | AH23: N/A | AI23: 100 | AJ23: 100.01
A24: 23 | B24: 국내 | C24: 45348 | D24: 현금 | E24: 민상구 | F24: 05C06 | G24: 한국투자TDF알아서증권투자신탁(채권혼합-재간접형)(C-e) | H24: 보통예금 | I24: 공통 | J24: KR9999990000 | L24: 예금 | M24: 0 | N24: 0 | O24: 0 | P24: 0 | Q24: 0 | R24: 0 | S24: 0 | T24: 0 | U24: 393977063 | V24: 1202.75 | Y24: 만기일시 | AA24: 0 | AB24: 2.99 | AC24: 0 | AD24: 2.99 | AE24: 0 | AF24: 우리은행 | AG24: 0 | AI24: 0 | AJ24: 0
A25: 24 | B25: 국내 | C25: 45348 | D25: 기타자산 | E25: 민상구 | F25: 05C08 | G25: 한국투자TDF알아서증권투자신탁(채권혼합-재간접형)(C-P) | H25: 계정코드 | J25: 1711700 | L25: 집합투자증권매도미수금 | M25: 0 | N25: 0 | O25: 0 | P25: 0 | Q25: 193495923 | R25: 193495923 | S25: 0 | T25: 0 | U25: 25668361919 | V25: 1223.62 | AA25: 0 | AB25: 0 | AC25: 0 | AD25: 0 | AE25: 0 | AF25: 우리은행 | AG25: 0 | AI25: 0.75 | AJ25: 0.75
A26: 25 | B26: 국내 | C26: 45348 | D26: 집합증권 | E26: 민상구 | F26: 05C08 | G26: 한국투자TDF알아서증권투자신탁(채권혼합-재간접형)(C-P) | H26: 종류형모펀드 | I26: 한국투자신탁운용 | J26: 032280005C02 | L26: 한국투자TDF알아서증권투자신탁(채권혼합-재간접형)(모) | M26: 20257535212 | N26: 24133405039 | O26: 1267.23 | P26: 1537566963 | Q26: 25670972002 | R26: 25670972002 | S26: 0 | T26: 0 | U26: 25668361919 | V26: 1223.62 | W26: 42788 | X26: 0000-01-01 | Y26: N/A | Z26: 45343 | AA26: 0 | AB26: 0 | AC26: 0 | AD26: 0 | AE26: 0 | AF26: 우리은행 | AG26: 0 | AH26: N/A | AI26: 99.25 | AJ26: 100.01
A27: 26 | B27: 국내 | C27: 45348 | D27: 현금 | E27: 민상구 | F27: 05C08 | G27: 한국투자TDF알아서증권투자신탁(채권혼합-재간접형)(C-P) | H27: 보통예금 | I27: 공통 | J27: KR9999990000 | L27: 예금 | M27: 0 | N27: 0 | O27: 0 | P27: 0 | Q27: 0 | R27: 0 | S27: 0 | T27: 0 | U27: 25668361919 | V27: 1223.62 | Y27: 만기일시 | AA27: 0 | AB27: 2.99 | AC27: 0 | AD27: 2.99 | AE27: 0 | AF27: 우리은행 | AG27: 0 | AI27: 0 | AJ27: 0
A28: 27 | B28: 국내 | C28: 45348 | D28: 기타자산 | E28: 민상구 | F28: 05C09 | G28: 한국투자TDF알아서증권투자신탁(채권혼합-재간접형)(C-R) | H28: 계정코드 | J28: 1711700 | L28: 집합투자증권매도미수금 | M28: 0 | N28: 0 | O28: 0 | P28: 0 | Q28: 850735150 | R28: 850735150 | S28: 0 | T28: 0 | U28: 97314544246 | V28: 1230.87 | AA28: 0 | AB28: 0 | AC28: 0 | AD28: 0 | AE28: 0 | AF28: 우리은행 | AG28: 0 | AI28: 0.87 | AJ28: 0.87
A29: 28 | B29: 국내 | C29: 45348 | D29: 집합증권 | E29: 민상구 | F29: 05C09 | G29: 한국투자TDF알아서증권투자신탁(채권혼합-재간접형)(C-R) | H29: 종류형모펀드 | I29: 한국투자신탁운용 | J29: 032280005C02 | L29: 한국투자TDF알아서증권투자신탁(채권혼합-재간접형)(모) | M29: 76799834342 | N29: 92673428957 | O29: 1267.23 | P29: 4649684467 | Q29: 97323113424 | R29: 97323113424 | S29: 0 | T29: 0 | U29: 97314544246 | V29: 1230.87 | W29: 42788 | X29: 0000-01-01 | Y29: N/A | Z29: 45343 | AA29: 0 | AB29: 0 | AC29: 0 | AD29: 0 | AE29: 0 | AF29: 우리은행 | AG29: 0 | AH29: N/A | AI29: 99.13 | AJ29: 100.01
A30: 29 | B30: 국내 | C30: 45348 | D30: 현금 | E30: 민상구 | F30: 05C09 | G30: 한국투자TDF알아서증권투자신탁(채권혼합-재간접형)(C-R) | H30: 보통예금 | I30: 공통 | J30: KR9999990000 | L30: 예금 | M30: 0 | N30: 0 | O30: 0 | P30: 0 | Q30: 0 | R30: 0 | S30: 0 | T30: 0 | U30: 97314544246 | V30: 1230.87 | Y30: 만기일시 | AA30: 0 | AB30: 2.99 | AC30: 0 | AD30: 2.99 | AE30: 0 | AF30: 우리은행 | AG30: 0 | AI30: 0 | AJ30: 0
A31: 30 | B31: 국내 | C31: 45348 | D31: 집합증권 | E31: 민상구 | F31: 05C11 | G31: 한국투자TDF알아서증권투자신탁(채권혼합-재간접형)(C-W) | H31: 종류형모펀드 | I31: 한국투자신탁운용 | J31: 032280005C02 | L31: 한국투자TDF알아서증권투자신탁(채권혼합-재간접형)(모) | M31: 253446 | N31: 312697 | O31: 1267.23 | P31: 8478 | Q31: 321175 | R31: 321175 | S31: 0 | T31: 0 | U31: 321170 | V31: 1191.91 | W31: 42788 | X31: 0000-01-01 | Y31: N/A | Z31: 45343 | AA31: 0 | AB31: 0 | AC31: 0 | AD31: 0 | AE31: 0 | AF31: 우리은행 | AG31: 0 | AH31: N/A | AI31: 100 | AJ31: 100
A32: 31 | B32: 국내 | C32: 45348 | D32: 현금 | E32: 민상구 | F32: 05C11 | G32: 한국투자TDF알아서증권투자신탁(채권혼합-재간접형)(C-W) | H32: 보통예금 | I32: 공통 | J32: KR9999990000 | L32: 예금 | M32: 0 | N32: 0 | O32: 0 | P32: 0 | Q32: 0 | R32: 0 | S32: 0 | T32: 0 | U32: 321170 | V32: 1191.91 | Y32: 만기일시 | AA32: 0 | AB32: 2.99 | AC32: 0 | AD32: 2.99 | AE32: 0 | AF32: 우리은행 | AG32: 0 | AI32: 0 | AJ32: 0
A33: 32 | B33: 국내 | C33: 45348 | D33: 집합증권 | E33: 민상구 | F33: 05C12 | G33: 한국투자TDF알아서증권투자신탁(채권혼합-재간접형)(S) | H33: 종류형모펀드 | I33: 한국투자신탁운용 | J33: 032280005C02 | L33: 한국투자TDF알아서증권투자신탁(채권혼합-재간접형)(모) | M33: 36487051 | N33: 47267485 | O33: 1267.23 | P33: -1029971 | Q33: 46237514 | R33: 46237514 | S33: 0 | T33: 0 | U33: 46235417 | V33: 1167.64 | W33: 42788 | X33: 0000-01-01 | Y33: N/A | Z33: 45343 | AA33: 0 | AB33: 0 | AC33: 0 | AD33: 0 | AE33: 0 | AF33: 우리은행 | AG33: 0 | AH33: N/A | AI33: 100 | AJ33: 100
A34: 33 | B34: 국내 | C34: 45348 | D34: 현금 | E34: 민상구 | F34: 05C12 | G34: 한국투자TDF알아서증권투자신탁(채권혼합-재간접형)(S) | H34: 보통예금 | I34: 공통 | J34: KR9999990000 | L34: 예금 | M34: 0 | N34: 0 | O34: 0 | P34: 0 | Q34: 0 | R34: 0 | S34: 0 | T34: 0 | U34: 46235417 | V34: 1167.64 | Y34: 만기일시 | AA34: 0 | AB34: 2.99 | AC34: 0 | AD34: 2.99 | AE34: 0 | AF34: 우리은행 | AG34: 0 | AI34: 0 | AJ34: 0
A35: 34 | B35: 국내 | C35: 45348 | D35: 집합증권 | E35: 민상구 | F35: 05C13 | G35: 한국투자TDF알아서증권투자신탁(채권혼합-재간접형)(S-P) | H35: 종류형모펀드 | I35: 한국투자신탁운용 | J35: 032280005C02 | L35: 한국투자TDF알아서증권투자신탁(채권혼합-재간접형)(모) | M35: 150612470 | N35: 190390489 | O35: 1267.23 | P35: 470268 | Q35: 190860757 | R35: 190860757 | S35: 0 | T35: 0 | U35: 190852061 | V35: 1190.1 | W35: 42788 | X35: 0000-01-01 | Y35: N/A | Z35: 45343 | AA35: 0 | AB35: 0 | AC35: 0 | AD35: 0 | AE35: 0 | AF35: 우리은행 | AG35: 0 | AH35: N/A | AI35: 100 | AJ35: 100
A36: 35 | B36: 국내 | C36: 45348 | D36: 현금 | E36: 민상구 | F36: 05C13 | G36: 한국투자TDF알아서증권투자신탁(채권혼합-재간접형)(S-P) | H36: 보통예금 | I36: 공통 | J36: KR9999990000 | L36: 예금 | M36: 0 | N36: 0 | O36: 0 | P36: 0 | Q36: 0 | R36: 0 | S36: 0 | T36: 0 | U36: 190852061 | V36: 1190.1 | Y36: 만기일시 | AA36: 0 | AB36: 2.99 | AC36: 0 | AD36: 2.99 | AE36: 0 | AF36: 우리은행 | AG36: 0 | AI36: 0 | AJ36: 0
A37: 36 | B37: 국내 | C37: 45348 | D37: 주식 | E37: 민상구 | F37: 05C14 | G37: 한국투자TDF알아서2020증권모투자신탁(채권혼합-재간접형) | H37: ETF(거래소)(채권) | I37: 한국투자KINDEXKIS종합채권(AA- | J37: KR7356540005 | L37: ACE 종합채권(AA-이상)KIS액티브 | M37: 47190 | N37: 4386937817 | O37: 100030 | P37: 333477883 | Q37: 4386937817 | R37: 4720415700 | S37: 0 | T37: 0 | U37: 79799550687 | V37: 1254.34 | AA37: 0 | AB37: 0 | AC37: 0 | AD37: 0 | AE37: 7.6 | AF37: 우리은행 | AG37: 0 | AI37: 5.88 | AJ37: 5.92
A38: 37 | B38: 국내 | C38: 45348 | D38: 현금 | E38: 민상구 | F38: 05C14 | G38: 한국투자TDF알아서2020증권모투자신탁(채권혼합-재간접형) | H38: 보통예금 | I38: 공통 | J38: KR9999990000 | L38: 예금 | M38: 848972461 | N38: 848972461 | O38: 0 | P38: 0 | Q38: 850729617 | R38: 850729617 | S38: 0 | T38: 1757156 | U38: 79799550687 | V38: 1254.34 | Y38: 만기일시 | AA38: 2.98383 | AB38: 2.99 | AC38: 0 | AD38: 2.99 | AE38: 0 | AF38: 우리은행 | AG38: 0 | AI38: 1.06 | AJ38: 1.07
A39: 38 | B39: 국내 | C39: 45348 | D39: 현금 | E39: 민상구 | F39: 05C14 | G39: 한국투자TDF알아서2020증권모투자신탁(채권혼합-재간접형) | H39: 콜론 | I39: 한국증권금융 | J39: KR9E22680009 | L39: 증권금융(콜론) | M39: 480140000 | N39: 480140000 | O39: 0 | P39: 0 | Q39: 480185778 | R39: 480185778 | S39: 0 | T39: 45778 | U39: 79799550687 | V39: 1254.34 | W39: 45348 | X39: 45349 | Y39: 만기일시 | AA39: 3.47969 | AB39: 3.48 | AC39: 0 | AD39: 3.48 | AE39: 0 | AF39: 우리은행 | AG39: 0 | AI39: 0.6 | AJ39: 0.6
A40: 39 | B40: 국내 | C40: 45348 | D40: 현금 | E40: 민상구 | F40: 05C14 | G40: 한국투자TDF알아서2020증권모투자신탁(채권혼합-재간접형) | H40: 콜론 | I40: 삼성증권 | J40: KR9E22680023 | L40: 삼성증권(콜론) | M40: 333600000 | N40: 333600000 | O40: 0 | P40: 0 | Q40: 333633543 | R40: 333633543 | S40: 0 | T40: 33543 | U40: 79799550687 | V40: 1254.34 | W40: 45348 | X40: 45349 | Y40: 만기일시 | AA40: 3.66965 | AB40: 3.67 | AC40: 0 | AD40: 3.67 | AE40: 0 | AF40: 우리은행 | AG40: 0 | AI40: 0.42 | AJ40: 0.42
...

Sheet 펀드현황
B1: 멀티에셋운용부 주요펀드 수익률 현황 | S1: 자금 현황 | AB1: 억원 | AI1: 1만달러
G2: 62 | H2: 65 | I2: 12 | J2: 15 | K2: 18 | L2: 24 | M2: 27 | N2: 30 | O2: 45 | P2: 39 | Q2: 47 | V2: 순설정액 | Z2: 자금 | AB2: KRW | AH2: 자금 | AI2: USD
B3: 구분 | C3: 펀드코드 | D3: 펀드명 | E3: 설정액 | F3: 순자산 | G3: 최초설정일 | H3: 기준가격 | I3: 1개월 | J3: 3개월 | K3: 6개월 | L3: 1년 | M3: 2년 | N3: 3년 | O3: YTD | P3: 설정이후 | Q3: YTD 초과 | S3: 구분 | T3: 펀드코드 | V3: T0 | W3: T1 | X3: T2 | Z3: T0 | AB3: T1 | AC3: T2 | AD3: T3 | AE3: T4 | AF3: T5 | AH3: T0 | AI3: T1 | AJ3: T2 | AK3: T3 | AL3: T4 | AM3: T5
B4: ETF 포커스 | C4: 07M02 | D4: TIF포커스 | E4: =AVERAGEIFS(#REF!,#REF!,펀드현황!$C4)/100000000 -> #REF! | F4: =IFERROR(VLOOKUP($T4,자금총괄!$B:$E,4,0)/100000000,"") -> 70.407549 | G4: =VLOOKUP($C4,'MOS4110'!$A:$BP,펀드현황!G$2,0) -> 44839 | H4: =VLOOKUP($C4,'MOS4110'!$A:$BP,펀드현황!H$2,0) -> 1160.9 | I4: =VLOOKUP($C4,'MOS4110'!$A:$BP,펀드현황!I$2,0) -> 1.4312 | J4: =VLOOKUP($C4,'MOS4110'!$A:$BP,펀드현황!J$2,0) -> 6.3709 | K4: =VLOOKUP($C4,'MOS4110'!$A:$BP,펀드현황!K$2,0) -> 8.7833 | L4: =VLOOKUP($C4,'MOS4110'!$A:$BP,펀드현황!L$2,0) -> 13.0673 | O4: =VLOOKUP($C4,'MOS4110'!$A:$BP,펀드현황!O$2,0) -> 2.7709 | P4: =VLOOKUP($C4,'MOS4110'!$A:$BP,펀드현황!P$2,0) -> 16.7092 | S4: TDF ETF포커스 | T4: =C4 -> 07M02 | V4: =IFERROR( ( SUMIFS(설정해지!$G:$G, 설정해지!$B:$B,펀드현황!$C4,설정해지!$F:$F,"KRW")-SUMIFS(설정해지!$H:$H, 설정해지!$B:$B,펀드현황!$C4,설정해지!$F:$F,"KRW") ) /100000000,"") -> -0.03280307 | W4: =IFERROR( ( SUMIFS(설정해지!$I:$I, 설정해지!$B:$B,펀드현황!$C4,설정해지!$F:$F,"KRW")-SUMIFS(설정해지!$J:$J, 설정해지!$B:$B,펀드현황!$C4,설정해지!$F:$F,"KRW") ) /100000000,"") -> -0.55384553 | X4: =IFERROR( ( SUMIFS(설정해지!$K:$K, 설정해지!$B:$B,펀드현황!$C4,설정해지!$F:$F,"KRW")-SUMIFS(설정해지!$L:$L, 설정해지!$B:$B,펀드현황!$C4,설정해지!$F:$F,"KRW") ) /100000000,"") -> 0 | Z4: =IFERROR( ( SUMIFS(자금총괄!$G:$G, 자금총괄!$B:$B,펀드현황!$C4,자금총괄!$F:$F,$AB$2) ) /100000000,"") -> 2.4151214 | AA4: =Z4/F4 -> 0.034302024 | AB4: =IFERROR( ( SUMIFS(자금총괄!$I:$I, 자금총괄!$B:$B,펀드현황!$C4,자금총괄!$F:$F,$AB$2) ) /100000000,"") -> 1.669243 | AC4: =IFERROR( ( SUMIFS(자금총괄!$K:$K, 자금총괄!$B:$B,펀드현황!$C4,자금총괄!$F:$F,$AB$2) ) /100000000,"") -> 1.669243 | AD4: =IFERROR( ( SUMIFS(자금총괄!$M:$M, 자금총괄!$B:$B,펀드현황!$C4,자금총괄!$F:$F,$AB$2) ) /100000000,"") -> 1.6689395 | AE4: =IFERROR( ( SUMIFS(자금총괄!$O:$O, 자금총괄!$B:$B,펀드현황!$C4,자금총괄!$F:$F,$AB$2) ) /100000000,"") -> 1.6689395 | AF4: =IFERROR( ( SUMIFS(자금총괄!$Q:$Q, 자금총괄!$B:$B,펀드현황!$C4,자금총괄!$F:$F,$AB$2) ) /100000000,"") -> 1.657445 | AH4: =IFERROR( ( SUMIFS(자금총괄!$G:$G, 자금총괄!$B:$B,펀드현황!$C4,자금총괄!$F:$F,$AI$2)/10000 ),"") -> 1.068655 | AI4: =IFERROR( ( SUMIFS(자금총괄!$I:$I, 자금총괄!$B:$B,펀드현황!$C4,자금총괄!$F:$F,$AI$2)/10000 ),"") -> 1.402764 | AJ4: =IFERROR((SUMIFS(자금총괄!$K:$K,자금총괄!$B:$B,펀드현황!$C4,자금총괄!$F:$F,$AI$2)/10000),"") -> 1.402764 | AK4: =IFERROR((SUMIFS(자금총괄!$M:$M,자금총괄!$B:$B,펀드현황!$C4,자금총괄!$F:$F,$AI$2)/10000),"") -> 1.402764 | AL4: =IFERROR( ( SUMIFS(자금총괄!$O:$O, 자금총괄!$B:$B,펀드현황!$C4,자금총괄!$F:$F,$AI$2) /10000 ),"") -> 1.402764 | AM4: =IFERROR( ( SUMIFS(자금총괄!$Q:$Q, 자금총괄!$B:$B,펀드현황!$C4,자금총괄!$F:$F,$AI$2) /10000 ),"") -> 1.402764
C5: 07J66 | D5: TDF포커스 2030 | E5: =AVERAGEIFS(#REF!,#REF!,펀드현황!$C5)/100000000 -> #REF! | F5: =IFERROR(VLOOKUP($T5,자금총괄!$B:$E,4,0)/100000000,"") -> 233.53491 | G5: =VLOOKUP($C5,'MOS4110'!$A:$BP,펀드현황!G$2,0) -> 44839 | H5: =VLOOKUP($C5,'MOS4110'!$A:$BP,펀드현황!H$2,0) -> 1181.93 | I5: =VLOOKUP($C5,'MOS4110'!$A:$BP,펀드현황!I$2,0) -> 1.7686 | J5: =VLOOKUP($C5,'MOS4110'!$A:$BP,펀드현황!J$2,0) -> 7.4638 | K5: =VLOOKUP($C5,'MOS4110'!$A:$BP,펀드현황!K$2,0) -> 10.0453 | L5: =VLOOKUP($C5,'MOS4110'!$A:$BP,펀드현황!L$2,0) -> 15.8539 | O5: =VLOOKUP($C5,'MOS4110'!$A:$BP,펀드현황!O$2,0) -> 3.7591 | P5: =VLOOKUP($C5,'MOS4110'!$A:$BP,펀드현황!P$2,0) -> 19.0515 | T5: =C5 -> 07J66 | V5: =IFERROR( ( SUMIFS(설정해지!$G:$G, 설정해지!$B:$B,펀드현황!$C5,설정해지!$F:$F,"KRW")-SUMIFS(설정해지!$H:$H, 설정해지!$B:$B,펀드현황!$C5,설정해지!$F:$F,"KRW") ) /100000000,"") -> 0.74624513 | W5: =IFERROR( ( SUMIFS(설정해지!$I:$I, 설정해지!$B:$B,펀드현황!$C5,설정해지!$F:$F,"KRW")-SUMIFS(설정해지!$J:$J, 설정해지!$B:$B,펀드현황!$C5,설정해지!$F:$F,"KRW") ) /100000000,"") -> 0.61598837 | X5: =IFERROR( ( SUMIFS(설정해지!$K:$K, 설정해지!$B:$B,펀드현황!$C5,설정해지!$F:$F,"KRW")-SUMIFS(설정해지!$L:$L, 설정해지!$B:$B,펀드현황!$C5,설정해지!$F:$F,"KRW") ) /100000000,"") -> -0.00859354 | Z5: =IFERROR( ( SUMIFS(자금총괄!$G:$G, 자금총괄!$B:$B,펀드현황!$C5,자금총괄!$F:$F,$AB$2) ) /100000000,"") -> 9.0635073 | AA5: =Z5/F5 -> 0.038810075 | AB5: =IFERROR( ( SUMIFS(자금총괄!$I:$I, 자금총괄!$B:$B,펀드현황!$C5,자금총괄!$F:$F,$AB$2) ) /100000000,"") -> 9.6794957 | AC5: =IFERROR( ( SUMIFS(자금총괄!$K:$K, 자금총괄!$B:$B,펀드현황!$C5,자금총괄!$F:$F,$AB$2) ) /100000000,"") -> 9.6709022 | AD5: =IFERROR( ( SUMIFS(자금총괄!$M:$M, 자금총괄!$B:$B,펀드현황!$C5,자금총괄!$F:$F,$AB$2) ) /100000000,"") -> 7.5152604 | AE5: =IFERROR( ( SUMIFS(자금총괄!$O:$O, 자금총괄!$B:$B,펀드현황!$C5,자금총괄!$F:$F,$AB$2) ) /100000000,"") -> 7.4115072 | AF5: =IFERROR( ( SUMIFS(자금총괄!$Q:$Q, 자금총괄!$B:$B,펀드현황!$C5,자금총괄!$F:$F,$AB$2) ) /100000000,"") -> 7.3361716 | AH5: =IFERROR( ( SUMIFS(자금총괄!$G:$G, 자금총괄!$B:$B,펀드현황!$C5,자금총괄!$F:$F,$AI$2)/10000 ),"") -> 6.172508 | AI5: =IFERROR( ( SUMIFS(자금총괄!$I:$I, 자금총괄!$B:$B,펀드현황!$C5,자금총괄!$F:$F,$AI$2)/10000 ),"") -> 4.072394 | AJ5: =IFERROR((SUMIFS(자금총괄!$K:$K,자금총괄!$B:$B,펀드현황!$C5,자금총괄!$F:$F,$AI$2)/10000),"") -> 4.072394 | AK5: =IFERROR((SUMIFS(자금총괄!$M:$M,자금총괄!$B:$B,펀드현황!$C5,자금총괄!$F:$F,$AI$2)/10000),"") -> 4.072394 | AL5: =IFERROR( ( SUMIFS(자금총괄!$O:$O, 자금총괄!$B:$B,펀드현황!$C5,자금총괄!$F:$F,$AI$2) /10000 ),"") -> 4.072394 | AM5: =IFERROR( ( SUMIFS(자금총괄!$Q:$Q, 자금총괄!$B:$B,펀드현황!$C5,자금총괄!$F:$F,$AI$2) /10000 ),"") -> 4.072394
C6: 07J71 | D6: TDF포커스 2035 | E6: =AVERAGEIFS(#REF!,#REF!,펀드현황!$C6)/100000000 -> #REF! | F6: =IFERROR(VLOOKUP($T6,자금총괄!$B:$E,4,0)/100000000,"") -> 71.524681 | G6: =VLOOKUP($C6,'MOS4110'!$A:$BP,펀드현황!G$2,0) -> 44839 | H6: =VLOOKUP($C6,'MOS4110'!$A:$BP,펀드현황!H$2,0) -> 1190.14 | I6: =VLOOKUP($C6,'MOS4110'!$A:$BP,펀드현황!I$2,0) -> 1.886 | J6: =VLOOKUP($C6,'MOS4110'!$A:$BP,펀드현황!J$2,0) -> 7.8387 | K6: =VLOOKUP($C6,'MOS4110'!$A:$BP,펀드현황!K$2,0) -> 10.4724 | L6: =VLOOKUP($C6,'MOS4110'!$A:$BP,펀드현황!L$2,0) -> 17.1602 | O6: =VLOOKUP($C6,'MOS4110'!$A:$BP,펀드현황!O$2,0) -> 4.0632 | P6: =VLOOKUP($C6,'MOS4110'!$A:$BP,펀드현황!P$2,0) -> 19.9123 | T6: =C6 -> 07J71 | V6: =IFERROR( ( SUMIFS(설정해지!$G:$G, 설정해지!$B:$B,펀드현황!$C6,설정해지!$F:$F,"KRW")-SUMIFS(설정해지!$H:$H, 설정해지!$B:$B,펀드현황!$C6,설정해지!$F:$F,"KRW") ) /100000000,"") -> 0.04599013 | W6: =IFERROR( ( SUMIFS(설정해지!$I:$I, 설정해지!$B:$B,펀드현황!$C6,설정해지!$F:$F,"KRW")-SUMIFS(설정해지!$J:$J, 설정해지!$B:$B,펀드현황!$C6,설정해지!$F:$F,"KRW") ) /100000000,"") -> 0.03775624 | X6: =IFERROR( ( SUMIFS(설정해지!$K:$K, 설정해지!$B:$B,펀드현황!$C6,설정해지!$F:$F,"KRW")-SUMIFS(설정해지!$L:$L, 설정해지!$B:$B,펀드현황!$C6,설정해지!$F:$F,"KRW") ) /100000000,"") -> 0 | Z6: =IFERROR( ( SUMIFS(자금총괄!$G:$G, 자금총괄!$B:$B,펀드현황!$C6,자금총괄!$F:$F,$AB$2) ) /100000000,"") -> 2.0060568 | AA6: =Z6/F6 -> 0.028047057 | AB6: =IFERROR( ( SUMIFS(자금총괄!$I:$I, 자금총괄!$B:$B,펀드현황!$C6,자금총괄!$F:$F,$AB$2) ) /100000000,"") -> 1.7095927 | AC6: =IFERROR( ( SUMIFS(자금총괄!$K:$K, 자금총괄!$B:$B,펀드현황!$C6,자금총괄!$F:$F,$AB$2) ) /100000000,"") -> 1.7095927 | AD6: =IFERROR( ( SUMIFS(자금총괄!$M:$M, 자금총괄!$B:$B,펀드현황!$C6,자금총괄!$F:$F,$AB$2) ) /100000000,"") -> 1.7095927 | AE6: =IFERROR( ( SUMIFS(자금총괄!$O:$O, 자금총괄!$B:$B,펀드현황!$C6,자금총괄!$F:$F,$AB$2) ) /100000000,"") -> 1.7095927 | AF6: =IFERROR( ( SUMIFS(자금총괄!$Q:$Q, 자금총괄!$B:$B,펀드현황!$C6,자금총괄!$F:$F,$AB$2) ) /100000000,"") -> 1.7095927 | AH6: =IFERROR( ( SUMIFS(자금총괄!$G:$G, 자금총괄!$B:$B,펀드현황!$C6,자금총괄!$F:$F,$AI$2)/10000 ),"") -> 1.394757 | AI6: =IFERROR( ( SUMIFS(자금총괄!$I:$I, 자금총괄!$B:$B,펀드현황!$C6,자금총괄!$F:$F,$AI$2)/10000 ),"") -> 1.639727 | AJ6: =IFERROR((SUMIFS(자금총괄!$K:$K,자금총괄!$B:$B,펀드현황!$C6,자금총괄!$F:$F,$AI$2)/10000),"") -> 1.639727 | AK6: =IFERROR((SUMIFS(자금총괄!$M:$M,자금총괄!$B:$B,펀드현황!$C6,자금총괄!$F:$F,$AI$2)/10000),"") -> 1.639727 | AL6: =IFERROR( ( SUMIFS(자금총괄!$O:$O, 자금총괄!$B:$B,펀드현황!$C6,자금총괄!$F:$F,$AI$2) /10000 ),"") -> 1.639727 | AM6: =IFERROR( ( SUMIFS(자금총괄!$Q:$Q, 자금총괄!$B:$B,펀드현황!$C6,자금총괄!$F:$F,$AI$2) /10000 ),"") -> 1.639727
C7: 07J76 | D7: TDF포커스 2040 | E7: =AVERAGEIFS(#REF!,#REF!,펀드현황!$C7)/100000000 -> #REF! | F7: =IFERROR(VLOOKUP($T7,자금총괄!$B:$E,4,0)/100000000,"") -> 58.585821 | G7: =VLOOKUP($C7,'MOS4110'!$A:$BP,펀드현황!G$2,0) -> 44839 | H7: =VLOOKUP($C7,'MOS4110'!$A:$BP,펀드현황!H$2,0) -> 1197.62 | I7: =VLOOKUP($C7,'MOS4110'!$A:$BP,펀드현황!I$2,0) -> 2.058 | J7: =VLOOKUP($C7,'MOS4110'!$A:$BP,펀드현황!J$2,0) -> 8.3976 | K7: =VLOOKUP($C7,'MOS4110'!$A:$BP,펀드현황!K$2,0) -> 11.094 | L7: =VLOOKUP($C7,'MOS4110'!$A:$BP,펀드현황!L$2,0) -> 18.4963 | O7: =VLOOKUP($C7,'MOS4110'!$A:$BP,펀드현황!O$2,0) -> 4.5664 | P7: =VLOOKUP($C7,'MOS4110'!$A:$BP,펀드현황!P$2,0) -> 20.7714 | T7: =C7 -> 07J76 | V7: =IFERROR( ( SUMIFS(설정해지!$G:$G, 설정해지!$B:$B,펀드현황!$C7,설정해지!$F:$F,"KRW")-SUMIFS(설정해지!$H:$H, 설정해지!$B:$B,펀드현황!$C7,설정해지!$F:$F,"KRW") ) /100000000,"") -> 0.31869655 | W7: =IFERROR( ( SUMIFS(설정해지!$I:$I, 설정해지!$B:$B,펀드현황!$C7,설정해지!$F:$F,"KRW")-SUMIFS(설정해지!$J:$J, 설정해지!$B:$B,펀드현황!$C7,설정해지!$F:$F,"KRW") ) /100000000,"") -> 0.14520328 | X7: =IFERROR( ( SUMIFS(설정해지!$K:$K, 설정해지!$B:$B,펀드현황!$C7,설정해지!$F:$F,"KRW")-SUMIFS(설정해지!$L:$L, 설정해지!$B:$B,펀드현황!$C7,설정해지!$F:$F,"KRW") ) /100000000,"") -> -0.15317858 | Z7: =IFERROR( ( SUMIFS(자금총괄!$G:$G, 자금총괄!$B:$B,펀드현황!$C7,자금총괄!$F:$F,$AB$2) ) /100000000,"") -> 2.0613932 | AA7: =Z7/F7 -> 0.035185872 | AB7: =IFERROR( ( SUMIFS(자금총괄!$I:$I, 자금총괄!$B:$B,펀드현황!$C7,자금총괄!$F:$F,$AB$2) ) /100000000,"") -> 1.9178655 | AC7: =IFERROR( ( SUMIFS(자금총괄!$K:$K, 자금총괄!$B:$B,펀드현황!$C7,자금총괄!$F:$F,$AB$2) ) /100000000,"") -> 1.7646869 | AD7: =IFERROR( ( SUMIFS(자금총괄!$M:$M, 자금총괄!$B:$B,펀드현황!$C7,자금총괄!$F:$F,$AB$2) ) /100000000,"") -> 1.7646869 | AE7: =IFERROR( ( SUMIFS(자금총괄!$O:$O, 자금총괄!$B:$B,펀드현황!$C7,자금총괄!$F:$F,$AB$2) ) /100000000,"") -> 1.7546815 | AF7: =IFERROR( ( SUMIFS(자금총괄!$Q:$Q, 자금총괄!$B:$B,펀드현황!$C7,자금총괄!$F:$F,$AB$2) ) /100000000,"") -> 1.6311358 | AH7: =IFERROR( ( SUMIFS(자금총괄!$G:$G, 자금총괄!$B:$B,펀드현황!$C7,자금총괄!$F:$F,$AI$2)/10000 ),"") -> 0.993986 | AI7: =IFERROR( ( SUMIFS(자금총괄!$I:$I, 자금총괄!$B:$B,펀드현황!$C7,자금총괄!$F:$F,$AI$2)/10000 ),"") -> 0.968188 | AJ7: =IFERROR((SUMIFS(자금총괄!$K:$K,자금총괄!$B:$B,펀드현황!$C7,자금총괄!$F:$F,$AI$2)/10000),"") -> 0.968188 | AK7: =IFERROR((SUMIFS(자금총괄!$M:$M,자금총괄!$B:$B,펀드현황!$C7,자금총괄!$F:$F,$AI$2)/10000),"") -> 0.968188 | AL7: =IFERROR( ( SUMIFS(자금총괄!$O:$O, 자금총괄!$B:$B,펀드현황!$C7,자금총괄!$F:$F,$AI$2) /10000 ),"") -> 0.968188 | AM7: =IFERROR( ( SUMIFS(자금총괄!$Q:$Q, 자금총괄!$B:$B,펀드현황!$C7,자금총괄!$F:$F,$AI$2) /10000 ),"") -> 0.968188
C8: 07J81 | D8: TDF포커스 2045 | E8: =AVERAGEIFS(#REF!,#REF!,펀드현황!$C8)/100000000 -> #REF! | F8: =IFERROR(VLOOKUP($T8,자금총괄!$B:$E,4,0)/100000000,"") -> 60.365321 | G8: =VLOOKUP($C8,'MOS4110'!$A:$BP,펀드현황!G$2,0) -> 44839 | H8: =VLOOKUP($C8,'MOS4110'!$A:$BP,펀드현황!H$2,0) -> 1204.52 | I8: =VLOOKUP($C8,'MOS4110'!$A:$BP,펀드현황!I$2,0) -> 2.2036 | J8: =VLOOKUP($C8,'MOS4110'!$A:$BP,펀드현황!J$2,0) -> 8.8773 | K8: =VLOOKUP($C8,'MOS4110'!$A:$BP,펀드현황!K$2,0) -> 11.6834 | L8: =VLOOKUP($C8,'MOS4110'!$A:$BP,펀드현황!L$2,0) -> 19.6567 | O8: =VLOOKUP($C8,'MOS4110'!$A:$BP,펀드현황!O$2,0) -> 4.9974 | P8: =VLOOKUP($C8,'MOS4110'!$A:$BP,펀드현황!P$2,0) -> 21.5461 | T8: =C8 -> 07J81 | V8: =IFERROR( ( SUMIFS(설정해지!$G:$G, 설정해지!$B:$B,펀드현황!$C8,설정해지!$F:$F,"KRW")-SUMIFS(설정해지!$H:$H, 설정해지!$B:$B,펀드현황!$C8,설정해지!$F:$F,"KRW") ) /100000000,"") -> -0.32146014 | W8: =IFERROR( ( SUMIFS(설정해지!$I:$I, 설정해지!$B:$B,펀드현황!$C8,설정해지!$F:$F,"KRW")-SUMIFS(설정해지!$J:$J, 설정해지!$B:$B,펀드현황!$C8,설정해지!$F:$F,"KRW") ) /100000000,"") -> 0.39074346 | X8: =IFERROR( ( SUMIFS(설정해지!$K:$K, 설정해지!$B:$B,펀드현황!$C8,설정해지!$F:$F,"KRW")-SUMIFS(설정해지!$L:$L, 설정해지!$B:$B,펀드현황!$C8,설정해지!$F:$F,"KRW") ) /100000000,"") -> 0 | Z8: =IFERROR( ( SUMIFS(자금총괄!$G:$G, 자금총괄!$B:$B,펀드현황!$C8,자금총괄!$F:$F,$AB$2) ) /100000000,"") -> 1.8607045 | AA8: =Z8/F8 -> 0.030824064 | AB8: =IFERROR( ( SUMIFS(자금총괄!$I:$I, 자금총괄!$B:$B,펀드현황!$C8,자금총괄!$F:$F,$AB$2) ) /100000000,"") -> 2.1445821 | AC8: =IFERROR( ( SUMIFS(자금총괄!$K:$K, 자금총괄!$B:$B,펀드현황!$C8,자금총괄!$F:$F,$AB$2) ) /100000000,"") -> 2.1445821 | AD8: =IFERROR( ( SUMIFS(자금총괄!$M:$M, 자금총괄!$B:$B,펀드현황!$C8,자금총괄!$F:$F,$AB$2) ) /100000000,"") -> 2.0967957 | AE8: =IFERROR( ( SUMIFS(자금총괄!$O:$O, 자금총괄!$B:$B,펀드현황!$C8,자금총괄!$F:$F,$AB$2) ) /100000000,"") -> 2.0967957 | AF8: =IFERROR( ( SUMIFS(자금총괄!$Q:$Q, 자금총괄!$B:$B,펀드현황!$C8,자금총괄!$F:$F,$AB$2) ) /100000000,"") -> 2.0548771 | AH8: =IFERROR( ( SUMIFS(자금총괄!$G:$G, 자금총괄!$B:$B,펀드현황!$C8,자금총괄!$F:$F,$AI$2)/10000 ),"") -> 0.892059 | AI8: =IFERROR( ( SUMIFS(자금총괄!$I:$I, 자금총괄!$B:$B,펀드현황!$C8,자금총괄!$F:$F,$AI$2)/10000 ),"") -> 0.739509 | AJ8: =IFERROR((SUMIFS(자금총괄!$K:$K,자금총괄!$B:$B,펀드현황!$C8,자금총괄!$F:$F,$AI$2)/10000),"") -> 0.739509 | AK8: =IFERROR((SUMIFS(자금총괄!$M:$M,자금총괄!$B:$B,펀드현황!$C8,자금총괄!$F:$F,$AI$2)/10000),"") -> 0.739509 | AL8: =IFERROR( ( SUMIFS(자금총괄!$O:$O, 자금총괄!$B:$B,펀드현황!$C8,자금총괄!$F:$F,$AI$2) /10000 ),"") -> 0.739509 | AM8: =IFERROR( ( SUMIFS(자금총괄!$Q:$Q, 자금총괄!$B:$B,펀드현황!$C8,자금총괄!$F:$F,$AI$2) /10000 ),"") -> 0.739509
C9: 07J86 | D9: TDF포커스 2050 | E9: =AVERAGEIFS(#REF!,#REF!,펀드현황!$C9)/100000000 -> #REF! | F9: =IFERROR(VLOOKUP($T9,자금총괄!$B:$E,4,0)/100000000,"") -> 111.81497 | G9: =VLOOKUP($C9,'MOS4110'!$A:$BP,펀드현황!G$2,0) -> 44839 | H9: =VLOOKUP($C9,'MOS4110'!$A:$BP,펀드현황!H$2,0) -> 1211.24 | I9: =VLOOKUP($C9,'MOS4110'!$A:$BP,펀드현황!I$2,0) -> 2.3335 | J9: =VLOOKUP($C9,'MOS4110'!$A:$BP,펀드현황!J$2,0) -> 9.3443 | K9: =VLOOKUP($C9,'MOS4110'!$A:$BP,펀드현황!K$2,0) -> 12.239 | L9: =VLOOKUP($C9,'MOS4110'!$A:$BP,펀드현황!L$2,0) -> 20.8402 | O9: =VLOOKUP($C9,'MOS4110'!$A:$BP,펀드현황!O$2,0) -> 5.4169 | P9: =VLOOKUP($C9,'MOS4110'!$A:$BP,펀드현황!P$2,0) -> 22.318 | T9: =C9 -> 07J86 | V9: =IFERROR( ( SUMIFS(설정해지!$G:$G, 설정해지!$B:$B,펀드현황!$C9,설정해지!$F:$F,"KRW")-SUMIFS(설정해지!$H:$H, 설정해지!$B:$B,펀드현황!$C9,설정해지!$F:$F,"KRW") ) /100000000,"") -> 2.8095287 | W9: =IFERROR( ( SUMIFS(설정해지!$I:$I, 설정해지!$B:$B,펀드현황!$C9,설정해지!$F:$F,"KRW")-SUMIFS(설정해지!$J:$J, 설정해지!$B:$B,펀드현황!$C9,설정해지!$F:$F,"KRW") ) /100000000,"") -> 1.4686764 | X9: =IFERROR( ( SUMIFS(설정해지!$K:$K, 설정해지!$B:$B,펀드현황!$C9,설정해지!$F:$F,"KRW")-SUMIFS(설정해지!$L:$L, 설정해지!$B:$B,펀드현황!$C9,설정해지!$F:$F,"KRW") ) /100000000,"") -> -0.0608907 | Z9: =IFERROR( ( SUMIFS(자금총괄!$G:$G, 자금총괄!$B:$B,펀드현황!$C9,자금총괄!$F:$F,$AB$2) ) /100000000,"") -> 7.5579431 | AA9: =Z9/F9 -> 0.067593302 | AB9: =IFERROR( ( SUMIFS(자금총괄!$I:$I, 자금총괄!$B:$B,펀드현황!$C9,자금총괄!$F:$F,$AB$2) ) /100000000,"") -> 6.9585463 | AC9: =IFERROR( ( SUMIFS(자금총괄!$K:$K, 자금총괄!$B:$B,펀드현황!$C9,자금총괄!$F:$F,$AB$2) ) /100000000,"") -> 6.8976556 | AD9: =IFERROR( ( SUMIFS(자금총괄!$M:$M, 자금총괄!$B:$B,펀드현황!$C9,자금총괄!$F:$F,$AB$2) ) /100000000,"") -> 5.5652163 | AE9: =IFERROR( ( SUMIFS(자금총괄!$O:$O, 자금총괄!$B:$B,펀드현황!$C9,자금총괄!$F:$F,$AB$2) ) /100000000,"") -> 5.5049144 | AF9: =IFERROR( ( SUMIFS(자금총괄!$Q:$Q, 자금총괄!$B:$B,펀드현황!$C9,자금총괄!$F:$F,$AB$2) ) /100000000,"") -> 5.45818 | AH9: =IFERROR( ( SUMIFS(자금총괄!$G:$G, 자금총괄!$B:$B,펀드현황!$C9,자금총괄!$F:$F,$AI$2)/10000 ),"") -> 1.606253 | AI9: =IFERROR( ( SUMIFS(자금총괄!$I:$I, 자금총괄!$B:$B,펀드현황!$C9,자금총괄!$F:$F,$AI$2)/10000 ),"") -> 2.32099 | AJ9: =IFERROR((SUMIFS(자금총괄!$K:$K,자금총괄!$B:$B,펀드현황!$C9,자금총괄!$F:$F,$AI$2)/10000),"") -> 2.32099 | AK9: =IFERROR((SUMIFS(자금총괄!$M:$M,자금총괄!$B:$B,펀드현황!$C9,자금총괄!$F:$F,$AI$2)/10000),"") -> 2.32099 | AL9: =IFERROR( ( SUMIFS(자금총괄!$O:$O, 자금총괄!$B:$B,펀드현황!$C9,자금총괄!$F:$F,$AI$2) /10000 ),"") -> 2.32099 | AM9: =IFERROR( ( SUMIFS(자금총괄!$Q:$Q, 자금총괄!$B:$B,펀드현황!$C9,자금총괄!$F:$F,$AI$2) /10000 ),"") -> 2.32099
C10: 07J91 | D10: TDF포커스 2055 | E10: =AVERAGEIFS(#REF!,#REF!,펀드현황!$C10)/100000000 -> #REF! | F10: =IFERROR(VLOOKUP($T10,자금총괄!$B:$E,4,0)/100000000,"") -> 62.690552 | G10: =VLOOKUP($C10,'MOS4110'!$A:$BP,펀드현황!G$2,0) -> 44839 | H10: =VLOOKUP($C10,'MOS4110'!$A:$BP,펀드현황!H$2,0) -> 1218.19 | I10: =VLOOKUP($C10,'MOS4110'!$A:$BP,펀드현황!I$2,0) -> 2.4929 | J10: =VLOOKUP($C10,'MOS4110'!$A:$BP,펀드현황!J$2,0) -> 9.7686 | K10: =VLOOKUP($C10,'MOS4110'!$A:$BP,펀드현황!K$2,0) -> 12.7369 | L10: =VLOOKUP($C10,'MOS4110'!$A:$BP,펀드현황!L$2,0) -> 21.8882 | O10: =VLOOKUP($C10,'MOS4110'!$A:$BP,펀드현황!O$2,0) -> 5.832 | P10: =VLOOKUP($C10,'MOS4110'!$A:$BP,펀드현황!P$2,0) -> 23.0839 | T10: =C10 -> 07J91 | V10: =IFERROR( ( SUMIFS(설정해지!$G:$G, 설정해지!$B:$B,펀드현황!$C10,설정해지!$F:$F,"KRW")-SUMIFS(설정해지!$H:$H, 설정해지!$B:$B,펀드현황!$C10,설정해지!$F:$F,"KRW") ) /100000000,"") -> 0.5496819 | W10: =IFERROR( ( SUMIFS(설정해지!$I:$I, 설정해지!$B:$B,펀드현황!$C10,설정해지!$F:$F,"KRW")-SUMIFS(설정해지!$J:$J, 설정해지!$B:$B,펀드현황!$C10,설정해지!$F:$F,"KRW") ) /100000000,"") -> 0.14821533 | X10: =IFERROR( ( SUMIFS(설정해지!$K:$K, 설정해지!$B:$B,펀드현황!$C10,설정해지!$F:$F,"KRW")-SUMIFS(설정해지!$L:$L, 설정해지!$B:$B,펀드현황!$C10,설정해지!$F:$F,"KRW") ) /100000000,"") -> 0 | Z10: =IFERROR( ( SUMIFS(자금총괄!$G:$G, 자금총괄!$B:$B,펀드현황!$C10,자금총괄!$F:$F,$AB$2) ) /100000000,"") -> 2.3884554 | AA10: =Z10/F10 -> 0.038099128 | AB10: =IFERROR( ( SUMIFS(자금총괄!$I:$I, 자금총괄!$B:$B,펀드현황!$C10,자금총괄!$F:$F,$AB$2) ) /100000000,"") -> 2.1439133 | AC10: =IFERROR( ( SUMIFS(자금총괄!$K:$K, 자금총괄!$B:$B,펀드현황!$C10,자금총괄!$F:$F,$AB$2) ) /100000000,"") -> 2.1439133 | AD10: =IFERROR( ( SUMIFS(자금총괄!$M:$M, 자금총괄!$B:$B,펀드현황!$C10,자금총괄!$F:$F,$AB$2) ) /100000000,"") -> 2.1439133 | AE10: =IFERROR( ( SUMIFS(자금총괄!$O:$O, 자금총괄!$B:$B,펀드현황!$C10,자금총괄!$F:$F,$AB$2) ) /100000000,"") -> 2.1439133 | AF10: =IFERROR( ( SUMIFS(자금총괄!$Q:$Q, 자금총괄!$B:$B,펀드현황!$C10,자금총괄!$F:$F,$AB$2) ) /100000000,"") -> 2.1390011 | AH10: =IFERROR( ( SUMIFS(자금총괄!$G:$G, 자금총괄!$B:$B,펀드현황!$C10,자금총괄!$F:$F,$AI$2)/10000 ),"") -> 0.983533 | AI10: =IFERROR( ( SUMIFS(자금총괄!$I:$I, 자금총괄!$B:$B,펀드현황!$C10,자금총괄!$F:$F,$AI$2)/10000 ),"") -> 0.901686 | AJ10: =IFERROR((SUMIFS(자금총괄!$K:$K,자금총괄!$B:$B,펀드현황!$C10,자금총괄!$F:$F,$AI$2)/10000),"") -> 0.901686 | AK10: =IFERROR((SUMIFS(자금총괄!$M:$M,자금총괄!$B:$B,펀드현황!$C10,자금총괄!$F:$F,$AI$2)/10000),"") -> 0.901686 | AL10: =IFERROR( ( SUMIFS(자금총괄!$O:$O, 자금총괄!$B:$B,펀드현황!$C10,자금총괄!$F:$F,$AI$2) /10000 ),"") -> 0.901686 | AM10: =IFERROR( ( SUMIFS(자금총괄!$Q:$Q, 자금총괄!$B:$B,펀드현황!$C10,자금총괄!$F:$F,$AI$2) /10000 ),"") -> 0.901686
C11: 07J96 | D11: TDF포커스 2060 | E11: =AVERAGEIFS(#REF!,#REF!,펀드현황!$C11)/100000000 -> #REF! | F11: =IFERROR(VLOOKUP($T11,자금총괄!$B:$E,4,0)/100000000,"") -> 140.11785 | G11: =VLOOKUP($C11,'MOS4110'!$A:$BP,펀드현황!G$2,0) -> 44839 | H11: =VLOOKUP($C11,'MOS4110'!$A:$BP,펀드현황!H$2,0) -> 1220.89 | I11: =VLOOKUP($C11,'MOS4110'!$A:$BP,펀드현황!I$2,0) -> 2.5958 | J11: =VLOOKUP($C11,'MOS4110'!$A:$BP,펀드현황!J$2,0) -> 10.0734 | K11: =VLOOKUP($C11,'MOS4110'!$A:$BP,펀드현황!K$2,0) -> 13.1373 | L11: =VLOOKUP($C11,'MOS4110'!$A:$BP,펀드현황!L$2,0) -> 22.4488 | O11: =VLOOKUP($C11,'MOS4110'!$A:$BP,펀드현황!O$2,0) -> 6.1247 | P11: =VLOOKUP($C11,'MOS4110'!$A:$BP,펀드현황!P$2,0) -> 23.4271 | T11: =C11 -> 07J96 | V11: =IFERROR( ( SUMIFS(설정해지!$G:$G, 설정해지!$B:$B,펀드현황!$C11,설정해지!$F:$F,"KRW")-SUMIFS(설정해지!$H:$H, 설정해지!$B:$B,펀드현황!$C11,설정해지!$F:$F,"KRW") ) /100000000,"") -> 1.4790166 | W11: =IFERROR( ( SUMIFS(설정해지!$I:$I, 설정해지!$B:$B,펀드현황!$C11,설정해지!$F:$F,"KRW")-SUMIFS(설정해지!$J:$J, 설정해지!$B:$B,펀드현황!$C11,설정해지!$F:$F,"KRW") ) /100000000,"") -> 1.2556603 | X11: =IFERROR( ( SUMIFS(설정해지!$K:$K, 설정해지!$B:$B,펀드현황!$C11,설정해지!$F:$F,"KRW")-SUMIFS(설정해지!$L:$L, 설정해지!$B:$B,펀드현황!$C11,설정해지!$F:$F,"KRW") ) /100000000,"") -> -0.67666634 | Z11: =IFERROR( ( SUMIFS(자금총괄!$G:$G, 자금총괄!$B:$B,펀드현황!$C11,자금총괄!$F:$F,$AB$2) ) /100000000,"") -> 7.466445 | AA11: =Z11/F11 -> 0.053286896 | AB11: =IFERROR( ( SUMIFS(자금총괄!$I:$I, 자금총괄!$B:$B,펀드현황!$C11,자금총괄!$F:$F,$AB$2) ) /100000000,"") -> 6.8197958 | AC11: =IFERROR( ( SUMIFS(자금총괄!$K:$K, 자금총괄!$B:$B,펀드현황!$C11,자금총괄!$F:$F,$AB$2) ) /100000000,"") -> 6.1431295 | AD11: =IFERROR( ( SUMIFS(자금총괄!$M:$M, 자금총괄!$B:$B,펀드현황!$C11,자금총괄!$F:$F,$AB$2) ) /100000000,"") -> 6.1237522 | AE11: =IFERROR( ( SUMIFS(자금총괄!$O:$O, 자금총괄!$B:$B,펀드현황!$C11,자금총괄!$F:$F,$AB$2) ) /100000000,"") -> 6.0763419 | AF11: =IFERROR( ( SUMIFS(자금총괄!$Q:$Q, 자금총괄!$B:$B,펀드현황!$C11,자금총괄!$F:$F,$AB$2) ) /100000000,"") -> 5.6725649 | AH11: =IFERROR( ( SUMIFS(자금총괄!$G:$G, 자금총괄!$B:$B,펀드현황!$C11,자금총괄!$F:$F,$AI$2)/10000 ),"") -> 1.943294 | AI11: =IFERROR( ( SUMIFS(자금총괄!$I:$I, 자금총괄!$B:$B,펀드현황!$C11,자금총괄!$F:$F,$AI$2)/10000 ),"") -> 2.406327 | AJ11: =IFERROR((SUMIFS(자금총괄!$K:$K,자금총괄!$B:$B,펀드현황!$C11,자금총괄!$F:$F,$AI$2)/10000),"") -> 2.406327 | AK11: =IFERROR((SUMIFS(자금총괄!$M:$M,자금총괄!$B:$B,펀드현황!$C11,자금총괄!$F:$F,$AI$2)/10000),"") -> 2.406327 | AL11: =IFERROR( ( SUMIFS(자금총괄!$O:$O, 자금총괄!$B:$B,펀드현황!$C11,자금총괄!$F:$F,$AI$2) /10000 ),"") -> 2.406327 | AM11: =IFERROR( ( SUMIFS(자금총괄!$Q:$Q, 자금총괄!$B:$B,펀드현황!$C11,자금총괄!$F:$F,$AI$2) /10000 ),"") -> 2.406327
D12: TDF포커스 합계 | E12: =SUM(E4:E11) -> #REF! | F12: =SUM(F4:F11) -> 809.04165 | V12: =IFERROR( ( SUMIFS(설정해지!$G:$G, 설정해지!$B:$B,펀드현황!$C12,설정해지!$F:$F,"KRW")-SUMIFS(설정해지!$H:$H, 설정해지!$B:$B,펀드현황!$C12,설정해지!$F:$F,"KRW") ) /100000000,"") -> 0 | W12: =IFERROR( ( SUMIFS(설정해지!$I:$I, 설정해지!$B:$B,펀드현황!$C12,설정해지!$F:$F,"KRW")-SUMIFS(설정해지!$J:$J, 설정해지!$B:$B,펀드현황!$C12,설정해지!$F:$F,"KRW") ) /100000000,"") -> 0 | X12: =IFERROR( ( SUMIFS(설정해지!$K:$K, 설정해지!$B:$B,펀드현황!$C12,설정해지!$F:$F,"KRW")-SUMIFS(설정해지!$L:$L, 설정해지!$B:$B,펀드현황!$C12,설정해지!$F:$F,"KRW") ) /100000000,"") -> 0 | Z12: =IFERROR( ( SUMIFS(자금총괄!$G:$G, 자금총괄!$B:$B,펀드현황!$C12,자금총괄!$F:$F,$AB$2) ) /100000000,"") -> 0 | AB12: =IFERROR( ( SUMIFS(자금총괄!$I:$I, 자금총괄!$B:$B,펀드현황!$C12,자금총괄!$F:$F,$AB$2) ) /100000000,"") -> 0 | AC12: =IFERROR( ( SUMIFS(자금총괄!$K:$K, 자금총괄!$B:$B,펀드현황!$C12,자금총괄!$F:$F,$AB$2) ) /100000000,"") -> 0 | AD12: =IFERROR( ( SUMIFS(자금총괄!$M:$M, 자금총괄!$B:$B,펀드현황!$C12,자금총괄!$F:$F,$AB$2) ) /100000000,"") -> 0 | AE12: =IFERROR( ( SUMIFS(자금총괄!$O:$O, 자금총괄!$B:$B,펀드현황!$C12,자금총괄!$F:$F,$AB$2) ) /100000000,"") -> 0 | AF12: =IFERROR( ( SUMIFS(자금총괄!$Q:$Q, 자금총괄!$B:$B,펀드현황!$C12,자금총괄!$F:$F,$AB$2) ) /100000000,"") -> 0 | AH12: =IFERROR( ( SUMIFS(자금총괄!$G:$G, 자금총괄!$B:$B,펀드현황!$C12,자금총괄!$F:$F,$AI$2)/10000 ),"") -> 0 | AI12: =IFERROR( ( SUMIFS(자금총괄!$I:$I, 자금총괄!$B:$B,펀드현황!$C12,자금총괄!$F:$F,$AI$2)/10000 ),"") -> 0 | AJ12: =IFERROR((SUMIFS(자금총괄!$K:$K,자금총괄!$B:$B,펀드현황!$C12,자금총괄!$F:$F,$AI$2)/10000),"") -> 0 | AK12: =IFERROR((SUMIFS(자금총괄!$M:$M,자금총괄!$B:$B,펀드현황!$C12,자금총괄!$F:$F,$AI$2)/10000),"") -> 0 | AL12: =IFERROR( ( SUMIFS(자금총괄!$O:$O, 자금총괄!$B:$B,펀드현황!$C12,자금총괄!$F:$F,$AI$2) /10000 ),"") -> 0 | AM12: =IFERROR( ( SUMIFS(자금총괄!$Q:$Q, 자금총괄!$B:$B,펀드현황!$C12,자금총괄!$F:$F,$AI$2) /10000 ),"") -> 0
V13: =IFERROR( ( SUMIFS(설정해지!$G:$G, 설정해지!$B:$B,펀드현황!$C13,설정해지!$F:$F,"KRW")-SUMIFS(설정해지!$H:$H, 설정해지!$B:$B,펀드현황!$C13,설정해지!$F:$F,"KRW") ) /100000000,"") -> 0 | W13: =IFERROR( ( SUMIFS(설정해지!$I:$I, 설정해지!$B:$B,펀드현황!$C13,설정해지!$F:$F,"KRW")-SUMIFS(설정해지!$J:$J, 설정해지!$B:$B,펀드현황!$C13,설정해지!$F:$F,"KRW") ) /100000000,"") -> 0 | X13: =IFERROR( ( SUMIFS(설정해지!$K:$K, 설정해지!$B:$B,펀드현황!$C13,설정해지!$F:$F,"KRW")-SUMIFS(설정해지!$L:$L, 설정해지!$B:$B,펀드현황!$C13,설정해지!$F:$F,"KRW") ) /100000000,"") -> 0 | Z13: =IFERROR( ( SUMIFS(자금총괄!$G:$G, 자금총괄!$B:$B,펀드현황!$C13,자금총괄!$F:$F,$AB$2) ) /100000000,"") -> 0 | AB13: =IFERROR( ( SUMIFS(자금총괄!$I:$I, 자금총괄!$B:$B,펀드현황!$C13,자금총괄!$F:$F,$AB$2) ) /100000000,"") -> 0 | AC13: =IFERROR( ( SUMIFS(자금총괄!$K:$K, 자금총괄!$B:$B,펀드현황!$C13,자금총괄!$F:$F,$AB$2) ) /100000000,"") -> 0 | AD13: =IFERROR( ( SUMIFS(자금총괄!$M:$M, 자금총괄!$B:$B,펀드현황!$C13,자금총괄!$F:$F,$AB$2) ) /100000000,"") -> 0 | AE13: =IFERROR( ( SUMIFS(자금총괄!$O:$O, 자금총괄!$B:$B,펀드현황!$C13,자금총괄!$F:$F,$AB$2) ) /100000000,"") -> 0 | AF13: =IFERROR( ( SUMIFS(자금총괄!$Q:$Q, 자금총괄!$B:$B,펀드현황!$C13,자금총괄!$F:$F,$AB$2) ) /100000000,"") -> 0 | AH13: =IFERROR( ( SUMIFS(자금총괄!$G:$G, 자금총괄!$B:$B,펀드현황!$C13,자금총괄!$F:$F,$AI$2)/10000 ),"") -> 0 | AI13: =IFERROR( ( SUMIFS(자금총괄!$I:$I, 자금총괄!$B:$B,펀드현황!$C13,자금총괄!$F:$F,$AI$2)/10000 ),"") -> 0 | AJ13: =IFERROR((SUMIFS(자금총괄!$K:$K,자금총괄!$B:$B,펀드현황!$C13,자금총괄!$F:$F,$AI$2)/10000),"") -> 0 | AK13: =IFERROR((SUMIFS(자금총괄!$M:$M,자금총괄!$B:$B,펀드현황!$C13,자금총괄!$F:$F,$AI$2)/10000),"") -> 0 | AL13: =IFERROR( ( SUMIFS(자금총괄!$O:$O, 자금총괄!$B:$B,펀드현황!$C13,자금총괄!$F:$F,$AI$2) /10000 ),"") -> 0 | AM13: =IFERROR( ( SUMIFS(자금총괄!$Q:$Q, 자금총괄!$B:$B,펀드현황!$C13,자금총괄!$F:$F,$AI$2) /10000 ),"") -> 0
B14: TRP TDF | C14: 05C16 | D14: =VLOOKUP(C14,'MOS4110'!$A:$B,2,0) -> 한국투자TDF알아서2020증권자투자신탁(채권혼합-재간접형)(모) | E14: =AVERAGEIFS(#REF!,#REF!,펀드현황!$C14)/100000000 -> #REF! | F14: =IFERROR(VLOOKUP($T14,자금총괄!$B:$E,4,0)/100000000,"") -> 634.28726 | G14: =VLOOKUP($C14,'MOS4110'!$A:$BP,펀드현황!G$2,0) -> 42796 | H14: =VLOOKUP($C14,'MOS4110'!$A:$BP,펀드현황!H$2,0) -> 1329.98 | I14: =VLOOKUP($C14,'MOS4110'!$A:$BP,펀드현황!I$2,0) -> 1.3527 | J14: =VLOOKUP($C14,'MOS4110'!$A:$BP,펀드현황!J$2,0) -> 5.637 | K14: =VLOOKUP($C14,'MOS4110'!$A:$BP,펀드현황!K$2,0) -> 6.5382 | L14: =VLOOKUP($C14,'MOS4110'!$A:$BP,펀드현황!L$2,0) -> 9.0636 | M14: =VLOOKUP($C14,'MOS4110'!$A:$BP,펀드현황!M$2,0) -> 3.4143 | N14: =VLOOKUP($C14,'MOS4110'!$A:$BP,펀드현황!N$2,0) -> -0.6723 | ... P14: =VLOOKUP($C14,'MOS4110'!$A:$BP,펀드현황!P$2,0) -> 34.9304 | S14: TDF/TIF | T14: =C14 -> 05C16 | V14: =IFERROR( ( SUMIFS(설정해지!$G:$G, 설정해지!$B:$B,펀드현황!$C14,설정해지!$F:$F,"KRW")-SUMIFS(설정해지!$H:$H, 설정해지!$B:$B,펀드현황!$C14,설정해지!$F:$F,"KRW") ) /100000000,"") -> 0.02116263 | W14: =IFERROR( ( SUMIFS(설정해지!$I:$I, 설정해지!$B:$B,펀드현황!$C14,설정해지!$F:$F,"KRW")-SUMIFS(설정해지!$J:$J, 설정해지!$B:$B,펀드현황!$C14,설정해지!$F:$F,"KRW") ) /100000000,"") -> -0.02402604 | X14: =IFERROR( ( SUMIFS(설정해지!$K:$K, 설정해지!$B:$B,펀드현황!$C14,설정해지!$F:$F,"KRW")-SUMIFS(설정해지!$L:$L, 설정해지!$B:$B,펀드현황!$C14,설정해지!$F:$F,"KRW") ) /100000000,"") -> -1.4511601 | Z14: =IFERROR( ( SUMIFS(자금총괄!$G:$G, 자금총괄!$B:$B,펀드현황!$C14,자금총괄!$F:$F,$AB$2) ) /100000000,"") -> 8.2981852 | AA14: =Z14/F14 -> 0.013082693 | AB14: =IFERROR( ( SUMIFS(자금총괄!$I:$I, 자금총괄!$B:$B,펀드현황!$C14,자금총괄!$F:$F,$AB$2) ) /100000000,"") -> 8.3323115 | AC14: =IFERROR( ( SUMIFS(자금총괄!$K:$K, 자금총괄!$B:$B,펀드현황!$C14,자금총괄!$F:$F,$AB$2) ) /100000000,"") -> 7.5150821 | AD14: =IFERROR( ( SUMIFS(자금총괄!$M:$M, 자금총괄!$B:$B,펀드현황!$C14,자금총괄!$F:$F,$AB$2) ) /100000000,"") -> 7.5426212 | AE14: =IFERROR( ( SUMIFS(자금총괄!$O:$O, 자금총괄!$B:$B,펀드현황!$C14,자금총괄!$F:$F,$AB$2) ) /100000000,"") -> 7.5852505 | AF14: =IFERROR( ( SUMIFS(자금총괄!$Q:$Q, 자금총괄!$B:$B,펀드현황!$C14,자금총괄!$F:$F,$AB$2) ) /100000000,"") -> 7.6169705 | AH14: =IFERROR( ( SUMIFS(자금총괄!$G:$G, 자금총괄!$B:$B,펀드현황!$C14,자금총괄!$F:$F,$AI$2)/10000 ),"") -> 0 | AI14: =IFERROR( ( SUMIFS(자금총괄!$I:$I, 자금총괄!$B:$B,펀드현황!$C14,자금총괄!$F:$F,$AI$2)/10000 ),"") -> 0 | AJ14: =IFERROR((SUMIFS(자금총괄!$K:$K,자금총괄!$B:$B,펀드현황!$C14,자금총괄!$F:$F,$AI$2)/10000),"") -> 0 | AK14: =IFERROR((SUMIFS(자금총괄!$M:$M,자금총괄!$B:$B,펀드현황!$C14,자금총괄!$F:$F,$AI$2)/10000),"") -> 0 | AL14: =IFERROR( ( SUMIFS(자금총괄!$O:$O, 자금총괄!$B:$B,펀드현황!$C14,자금총괄!$F:$F,$AI$2) /10000 ),"") -> 0 | AM14: =IFERROR( ( SUMIFS(자금총괄!$Q:$Q, 자금총괄!$B:$B,펀드현황!$C14,자금총괄!$F:$F,$AI$2) /10000 ),"") -> 0
C15: 05K82 | D15: =VLOOKUP(C15,'MOS4110'!$A:$B,2,0) -> 한국투자신종개인연금TDF알아서2020증권자투자신탁(채권혼합-재 | E15: =AVERAGEIFS(#REF!,#REF!,펀드현황!$C15)/100000000 -> #REF! | F15: =IFERROR(VLOOKUP($T15,자금총괄!$B:$E,4,0)/100000000,"") -> 172.9328 | G15: =VLOOKUP($C15,'MOS4110'!$A:$BP,펀드현황!G$2,0) -> 42970 | H15: =VLOOKUP($C15,'MOS4110'!$A:$BP,펀드현황!H$2,0) -> 973.21 | I15: =VLOOKUP($C15,'MOS4110'!$A:$BP,펀드현황!I$2,0) -> 1.3528 | J15: =VLOOKUP($C15,'MOS4110'!$A:$BP,펀드현황!J$2,0) -> 5.6425 | K15: =VLOOKUP($C15,'MOS4110'!$A:$BP,펀드현황!K$2,0) -> 6.5469 | L15: =VLOOKUP($C15,'MOS4110'!$A:$BP,펀드현황!L$2,0) -> 9.0725 | M15: =VLOOKUP($C15,'MOS4110'!$A:$BP,펀드현황!M$2,0) -> 3.3779 | N15: =VLOOKUP($C15,'MOS4110'!$A:$BP,펀드현황!N$2,0) -> -0.727 | ... P15: =VLOOKUP($C15,'MOS4110'!$A:$BP,펀드현황!P$2,0) -> 27.7214 | T15: =C15 -> 05K82 | V15: =IFERROR( ( SUMIFS(설정해지!$G:$G, 설정해지!$B:$B,펀드현황!$C15,설정해지!$F:$F,"KRW")-SUMIFS(설정해지!$H:$H, 설정해지!$B:$B,펀드현황!$C15,설정해지!$F:$F,"KRW") ) /100000000,"") -> -0.00624195 | W15: =IFERROR( ( SUMIFS(설정해지!$I:$I, 설정해지!$B:$B,펀드현황!$C15,설정해지!$F:$F,"KRW")-SUMIFS(설정해지!$J:$J, 설정해지!$B:$B,펀드현황!$C15,설정해지!$F:$F,"KRW") ) /100000000,"") -> -0.80452006 | X15: =IFERROR( ( SUMIFS(설정해지!$K:$K, 설정해지!$B:$B,펀드현황!$C15,설정해지!$F:$F,"KRW")-SUMIFS(설정해지!$L:$L, 설정해지!$B:$B,펀드현황!$C15,설정해지!$F:$F,"KRW") ) /100000000,"") -> 0 | Z15: =IFERROR( ( SUMIFS(자금총괄!$G:$G, 자금총괄!$B:$B,펀드현황!$C15,자금총괄!$F:$F,$AB$2) ) /100000000,"") -> 2.2171244 | AA15: =Z15/F15 -> 0.012820728 | AB15: =IFERROR( ( SUMIFS(자금총괄!$I:$I, 자금총괄!$B:$B,펀드현황!$C15,자금총괄!$F:$F,$AB$2) ) /100000000,"") -> 2.244998 | AC15: =IFERROR( ( SUMIFS(자금총괄!$K:$K, 자금총괄!$B:$B,펀드현황!$C15,자금총괄!$F:$F,$AB$2) ) /100000000,"") -> 2.244998 | AD15: =IFERROR( ( SUMIFS(자금총괄!$M:$M, 자금총괄!$B:$B,펀드현황!$C15,자금총괄!$F:$F,$AB$2) ) /100000000,"") -> 2.244998 | AE15: =IFERROR( ( SUMIFS(자금총괄!$O:$O, 자금총괄!$B:$B,펀드현황!$C15,자금총괄!$F:$F,$AB$2) ) /100000000,"") -> 2.2459769 | AF15: =IFERROR( ( SUMIFS(자금총괄!$Q:$Q, 자금총괄!$B:$B,펀드현황!$C15,자금총괄!$F:$F,$AB$2) ) /100000000,"") -> 2.2463947 | AH15: =IFERROR( ( SUMIFS(자금총괄!$G:$G, 자금총괄!$B:$B,펀드현황!$C15,자금총괄!$F:$F,$AI$2)/10000 ),"") -> 0 | AI15: =IFERROR( ( SUMIFS(자금총괄!$I:$I, 자금총괄!$B:$B,펀드현황!$C15,자금총괄!$F:$F,$AI$2)/10000 ),"") -> 0 | AJ15: =IFERROR((SUMIFS(자금총괄!$K:$K,자금총괄!$B:$B,펀드현황!$C15,자금총괄!$F:$F,$AI$2)/10000),"") -> 0 | AK15: =IFERROR((SUMIFS(자금총괄!$M:$M,자금총괄!$B:$B,펀드현황!$C15,자금총괄!$F:$F,$AI$2)/10000),"") -> 0 | AL15: =IFERROR( ( SUMIFS(자금총괄!$O:$O, 자금총괄!$B:$B,펀드현황!$C15,자금총괄!$F:$F,$AI$2) /10000 ),"") -> 0 | AM15: =IFERROR( ( SUMIFS(자금총괄!$Q:$Q, 자금총괄!$B:$B,펀드현황!$C15,자금총괄!$F:$F,$AI$2) /10000 ),"") -> 0
C16: 05C30 | D16: =VLOOKUP(C16,'MOS4110'!$A:$B,2,0) -> 한국투자TDF알아서2025증권투자신탁(주식혼합-재간접형)(모) | E16: =AVERAGEIFS(#REF!,#REF!,펀드현황!$C16)/100000000 -> #REF! | F16: =IFERROR(VLOOKUP($T16,자금총괄!$B:$E,4,0)/100000000,"") -> 1367.042 | G16: =VLOOKUP($C16,'MOS4110'!$A:$BP,펀드현황!G$2,0) -> 42796 | H16: =VLOOKUP($C16,'MOS4110'!$A:$BP,펀드현황!H$2,0) -> 1363.72 | I16: =VLOOKUP($C16,'MOS4110'!$A:$BP,펀드현황!I$2,0) -> 1.462 | J16: =VLOOKUP($C16,'MOS4110'!$A:$BP,펀드현황!J$2,0) -> 5.8542 | K16: =VLOOKUP($C16,'MOS4110'!$A:$BP,펀드현황!K$2,0) -> 6.7742 | L16: =VLOOKUP($C16,'MOS4110'!$A:$BP,펀드현황!L$2,0) -> 9.6236 | M16: =VLOOKUP($C16,'MOS4110'!$A:$BP,펀드현황!M$2,0) -> 3.9481 | N16: =VLOOKUP($C16,'MOS4110'!$A:$BP,펀드현황!N$2,0) -> -0.5115 | ... P16: =VLOOKUP($C16,'MOS4110'!$A:$BP,펀드현황!P$2,0) -> 38.2916 | T16: =C16 -> 05C30 | V16: =IFERROR( ( SUMIFS(설정해지!$G:$G, 설정해지!$B:$B,펀드현황!$C16,설정해지!$F:$F,"KRW")-SUMIFS(설정해지!$H:$H, 설정해지!$B:$B,펀드현황!$C16,설정해지!$F:$F,"KRW") ) /100000000,"") -> -19.319884 | W16: =IFERROR( ( SUMIFS(설정해지!$I:$I, 설정해지!$B:$B,펀드현황!$C16,설정해지!$F:$F,"KRW")-SUMIFS(설정해지!$J:$J, 설정해지!$B:$B,펀드현황!$C16,설정해지!$F:$F,"KRW") ) /100000000,"") -> -0.32175583 | X16: =IFERROR( ( SUMIFS(설정해지!$K:$K, 설정해지!$B:$B,펀드현황!$C16,설정해지!$F:$F,"KRW")-SUMIFS(설정해지!$L:$L, 설정해지!$B:$B,펀드현황!$C16,설정해지!$F:$F,"KRW") ) /100000000,"") -> -3.6648606 | Z16: =IFERROR( ( SUMIFS(자금총괄!$G:$G, 자금총괄!$B:$B,펀드현황!$C16,자금총괄!$F:$F,$AB$2) ) /100000000,"") -> 38.793 | AA16: =Z16/F16 -> 0.028377329 | AB16: =IFERROR( ( SUMIFS(자금총괄!$I:$I, 자금총괄!$B:$B,펀드현황!$C16,자금총괄!$F:$F,$AB$2) ) /100000000,"") -> 38.471244 | AC16: =IFERROR( ( SUMIFS(자금총괄!$K:$K, 자금총괄!$B:$B,펀드현황!$C16,자금총괄!$F:$F,$AB$2) ) /100000000,"") -> 34.806384 | AD16: =IFERROR( ( SUMIFS(자금총괄!$M:$M, 자금총괄!$B:$B,펀드현황!$C16,자금총괄!$F:$F,$AB$2) ) /100000000,"") -> 34.423089 | AE16: =IFERROR( ( SUMIFS(자금총괄!$O:$O, 자금총괄!$B:$B,펀드현황!$C16,자금총괄!$F:$F,$AB$2) ) /100000000,"") -> 30.726909 | AF16: =IFERROR( ( SUMIFS(자금총괄!$Q:$Q, 자금총괄!$B:$B,펀드현황!$C16,자금총괄!$F:$F,$AB$2) ) /100000000,"") -> 329.71286 | AH16: =IFERROR( ( SUMIFS(자금총괄!$G:$G, 자금총괄!$B:$B,펀드현황!$C16,자금총괄!$F:$F,$AI$2)/10000 ),"") -> 0.056421 | AI16: =IFERROR( ( SUMIFS(자금총괄!$I:$I, 자금총괄!$B:$B,펀드현황!$C16,자금총괄!$F:$F,$AI$2)/10000 ),"") -> 0.056421 | AJ16: =IFERROR((SUMIFS(자금총괄!$K:$K,자금총괄!$B:$B,펀드현황!$C16,자금총괄!$F:$F,$AI$2)/10000),"") -> 0.056421 | AK16: =IFERROR((SUMIFS(자금총괄!$M:$M,자금총괄!$B:$B,펀드현황!$C16,자금총괄!$F:$F,$AI$2)/10000),"") -> 0.056421 | AL16: =IFERROR( ( SUMIFS(자금총괄!$O:$O, 자금총괄!$B:$B,펀드현황!$C16,자금총괄!$F:$F,$AI$2) /10000 ),"") -> 0.056421 | AM16: =IFERROR( ( SUMIFS(자금총괄!$Q:$Q, 자금총괄!$B:$B,펀드현황!$C16,자금총괄!$F:$F,$AI$2) /10000 ),"") -> -2308.9436
C17: 05C44 | D17: =VLOOKUP(C17,'MOS4110'!$A:$B,2,0) -> 한국투자TDF알아서2030증권투자신탁(주식혼합-재간접형)(모) | E17: =AVERAGEIFS(#REF!,#REF!,펀드현황!$C17)/100000000 -> #REF! | F17: =IFERROR(VLOOKUP($T17,자금총괄!$B:$E,4,0)/100000000,"") -> 2790.7718 | G17: =VLOOKUP($C17,'MOS4110'!$A:$BP,펀드현황!G$2,0) -> 42796 | H17: =VLOOKUP($C17,'MOS4110'!$A:$BP,펀드현황!H$2,0) -> 1447.07 | I17: =VLOOKUP($C17,'MOS4110'!$A:$BP,펀드현황!I$2,0) -> 2.0897 | J17: =VLOOKUP($C17,'MOS4110'!$A:$BP,펀드현황!J$2,0) -> 6.9401 | K17: =VLOOKUP($C17,'MOS4110'!$A:$BP,펀드현황!K$2,0) -> 7.9863 | L17: =VLOOKUP($C17,'MOS4110'!$A:$BP,펀드현황!L$2,0) -> 11.6024 | M17: =VLOOKUP($C17,'MOS4110'!$A:$BP,펀드현황!M$2,0) -> 6.2952 | N17: =VLOOKUP($C17,'MOS4110'!$A:$BP,펀드현황!N$2,0) -> 1.9481 | ... P17: =VLOOKUP($C17,'MOS4110'!$A:$BP,펀드현황!P$2,0) -> 46.773 | T17: =C17 -> 05C44 | V17: =IFERROR( ( SUMIFS(설정해지!$G:$G, 설정해지!$B:$B,펀드현황!$C17,설정해지!$F:$F,"KRW")-SUMIFS(설정해지!$H:$H, 설정해지!$B:$B,펀드현황!$C17,설정해지!$F:$F,"KRW") ) /100000000,"") -> -1.2525133 | W17: =IFERROR( ( SUMIFS(설정해지!$I:$I, 설정해지!$B:$B,펀드현황!$C17,설정해지!$F:$F,"KRW")-SUMIFS(설정해지!$J:$J, 설정해지!$B:$B,펀드현황!$C17,설정해지!$F:$F,"KRW") ) /100000000,"") -> 0.44025064 | X17: =IFERROR( ( SUMIFS(설정해지!$K:$K, 설정해지!$B:$B,펀드현황!$C17,설정해지!$F:$F,"KRW")-SUMIFS(설정해지!$L:$L, 설정해지!$B:$B,펀드현황!$C17,설정해지!$F:$F,"KRW") ) /100000000,"") -> -7.8152405 | Z17: =IFERROR( ( SUMIFS(자금총괄!$G:$G, 자금총괄!$B:$B,펀드현황!$C17,자금총괄!$F:$F,$AB$2) ) /100000000,"") -> 74.387464 | AA17: =Z17/F17 -> 0.0266548 | AB17: =IFERROR( ( SUMIFS(자금총괄!$I:$I, 자금총괄!$B:$B,펀드현황!$C17,자금총괄!$F:$F,$AB$2) ) /100000000,"") -> 74.827715 | AC17: =IFERROR( ( SUMIFS(자금총괄!$K:$K, 자금총괄!$B:$B,펀드현황!$C17,자금총괄!$F:$F,$AB$2) ) /100000000,"") -> 67.012475 | AD17: =IFERROR( ( SUMIFS(자금총괄!$M:$M, 자금총괄!$B:$B,펀드현황!$C17,자금총괄!$F:$F,$AB$2) ) /100000000,"") -> 63.133015 | AE17: =IFERROR( ( SUMIFS(자금총괄!$O:$O, 자금총괄!$B:$B,펀드현황!$C17,자금총괄!$F:$F,$AB$2) ) /100000000,"") -> 62.035324 | AF17: =IFERROR( ( SUMIFS(자금총괄!$Q:$Q, 자금총괄!$B:$B,펀드현황!$C17,자금총괄!$F:$F,$AB$2) ) /100000000,"") -> 548.99742 | AH17: =IFERROR( ( SUMIFS(자금총괄!$G:$G, 자금총괄!$B:$B,펀드현황!$C17,자금총괄!$F:$F,$AI$2)/10000 ),"") -> 0.016561 | AI17: =IFERROR( ( SUMIFS(자금총괄!$I:$I, 자금총괄!$B:$B,펀드현황!$C17,자금총괄!$F:$F,$AI$2)/10000 ),"") -> 0.016561 | AJ17: =IFERROR((SUMIFS(자금총괄!$K:$K,자금총괄!$B:$B,펀드현황!$C17,자금총괄!$F:$F,$AI$2)/10000),"") -> 0.016561 | AK17: =IFERROR((SUMIFS(자금총괄!$M:$M,자금총괄!$B:$B,펀드현황!$C17,자금총괄!$F:$F,$AI$2)/10000),"") -> 0.016561 | AL17: =IFERROR( ( SUMIFS(자금총괄!$O:$O, 자금총괄!$B:$B,펀드현황!$C17,자금총괄!$F:$F,$AI$2) /10000 ),"") -> 0.016561 | AM17: =IFERROR( ( SUMIFS(자금총괄!$Q:$Q, 자금총괄!$B:$B,펀드현황!$C17,자금총괄!$F:$F,$AI$2) /10000 ),"") -> -3762.9834
C18: 05C58 | D18: =VLOOKUP(C18,'MOS4110'!$A:$B,2,0) -> 한국투자TDF알아서2035증권투자신탁(주식혼합-재간접형)(모) | E18: =AVERAGEIFS(#REF!,#REF!,펀드현황!$C18)/100000000 -> #REF! | F18: =IFERROR(VLOOKUP($T18,자금총괄!$B:$E,4,0)/100000000,"") -> 1486.1227 | G18: =VLOOKUP($C18,'MOS4110'!$A:$BP,펀드현황!G$2,0) -> 42796 | H18: =VLOOKUP($C18,'MOS4110'!$A:$BP,펀드현황!H$2,0) -> 1509.55 | I18: =VLOOKUP($C18,'MOS4110'!$A:$BP,펀드현황!I$2,0) -> 2.5558 | J18: =VLOOKUP($C18,'MOS4110'!$A:$BP,펀드현황!J$2,0) -> 7.7519 | K18: =VLOOKUP($C18,'MOS4110'!$A:$BP,펀드현황!K$2,0) -> 8.889 | L18: =VLOOKUP($C18,'MOS4110'!$A:$BP,펀드현황!L$2,0) -> 13.1327 | M18: =VLOOKUP($C18,'MOS4110'!$A:$BP,펀드현황!M$2,0) -> 7.9405 | N18: =VLOOKUP($C18,'MOS4110'!$A:$BP,펀드현황!N$2,0) -> 3.3419 | ... P18: =VLOOKUP($C18,'MOS4110'!$A:$BP,펀드현황!P$2,0) -> 53.1097 | T18: =C18 -> 05C58 | V18: =IFERROR( ( SUMIFS(설정해지!$G:$G, 설정해지!$B:$B,펀드현황!$C18,설정해지!$F:$F,"KRW")-SUMIFS(설정해지!$H:$H, 설정해지!$B:$B,펀드현황!$C18,설정해지!$F:$F,"KRW") ) /100000000,"") -> -0.17814913 | W18: =IFERROR( ( SUMIFS(설정해지!$I:$I, 설정해지!$B:$B,펀드현황!$C18,설정해지!$F:$F,"KRW")-SUMIFS(설정해지!$J:$J, 설정해지!$B:$B,펀드현황!$C18,설정해지!$F:$F,"KRW") ) /100000000,"") -> 0.7920524 | X18: =IFERROR( ( SUMIFS(설정해지!$K:$K, 설정해지!$B:$B,펀드현황!$C18,설정해지!$F:$F,"KRW")-SUMIFS(설정해지!$L:$L, 설정해지!$B:$B,펀드현황!$C18,설정해지!$F:$F,"KRW") ) /100000000,"") -> -3.4830989 | Z18: =IFERROR( ( SUMIFS(자금총괄!$G:$G, 자금총괄!$B:$B,펀드현황!$C18,자금총괄!$F:$F,$AB$2) ) /100000000,"") -> 46.81667 | AA18: =Z18/F18 -> 0.031502559 | AB18: =IFERROR( ( SUMIFS(자금총괄!$I:$I, 자금총괄!$B:$B,펀드현황!$C18,자금총괄!$F:$F,$AB$2) ) /100000000,"") -> 47.608722 | AC18: =IFERROR( ( SUMIFS(자금총괄!$K:$K, 자금총괄!$B:$B,펀드현황!$C18,자금총괄!$F:$F,$AB$2) ) /100000000,"") -> 44.125623 | AD18: =IFERROR( ( SUMIFS(자금총괄!$M:$M, 자금총괄!$B:$B,펀드현황!$C18,자금총괄!$F:$F,$AB$2) ) /100000000,"") -> 43.923812 | AE18: =IFERROR( ( SUMIFS(자금총괄!$O:$O, 자금총괄!$B:$B,펀드현황!$C18,자금총괄!$F:$F,$AB$2) ) /100000000,"") -> 43.162089 | AF18: =IFERROR( ( SUMIFS(자금총괄!$Q:$Q, 자금총괄!$B:$B,펀드현황!$C18,자금총괄!$F:$F,$AB$2) ) /100000000,"") -> 294.79273 | AH18: =IFERROR( ( SUMIFS(자금총괄!$G:$G, 자금총괄!$B:$B,펀드현황!$C18,자금총괄!$F:$F,$AI$2)/10000 ),"") -> 4.658794 | AI18: =IFERROR( ( SUMIFS(자금총괄!$I:$I, 자금총괄!$B:$B,펀드현황!$C18,자금총괄!$F:$F,$AI$2)/10000 ),"") -> 4.658794 | AJ18: =IFERROR((SUMIFS(자금총괄!$K:$K,자금총괄!$B:$B,펀드현황!$C18,자금총괄!$F:$F,$AI$2)/10000),"") -> 4.658794 | AK18: =IFERROR((SUMIFS(자금총괄!$M:$M,자금총괄!$B:$B,펀드현황!$C18,자금총괄!$F:$F,$AI$2)/10000),"") -> 4.658794 | AL18: =IFERROR( ( SUMIFS(자금총괄!$O:$O, 자금총괄!$B:$B,펀드현황!$C18,자금총괄!$F:$F,$AI$2) /10000 ),"") -> 4.658794 | AM18: =IFERROR( ( SUMIFS(자금총괄!$Q:$Q, 자금총괄!$B:$B,펀드현황!$C18,자금총괄!$F:$F,$AI$2) /10000 ),"") -> -1943.3412
C19: 05C72 | D19: =VLOOKUP(C19,'MOS4110'!$A:$B,2,0) -> 한국투자TDF알아서2040증권투자신탁(주식혼합-재간접형)(모) | E19: =AVERAGEIFS(#REF!,#REF!,펀드현황!$C19)/100000000 -> #REF! | F19: =IFERROR(VLOOKUP($T19,자금총괄!$B:$E,4,0)/100000000,"") -> 2049.1878 | G19: =VLOOKUP($C19,'MOS4110'!$A:$BP,펀드현황!G$2,0) -> 42796 | H19: =VLOOKUP($C19,'MOS4110'!$A:$BP,펀드현황!H$2,0) -> 1567 | I19: =VLOOKUP($C19,'MOS4110'!$A:$BP,펀드현황!I$2,0) -> 2.8965 | J19: =VLOOKUP($C19,'MOS4110'!$A:$BP,펀드현황!J$2,0) -> 8.3222 | K19: =VLOOKUP($C19,'MOS4110'!$A:$BP,펀드현황!K$2,0) -> 9.484 | L19: =VLOOKUP($C19,'MOS4110'!$A:$BP,펀드현황!L$2,0) -> 14.0718 | M19: =VLOOKUP($C19,'MOS4110'!$A:$BP,펀드현황!M$2,0) -> 9.1878 | N19: =VLOOKUP($C19,'MOS4110'!$A:$BP,펀드현황!N$2,0) -> 4.66 | ... P19: =VLOOKUP($C19,'MOS4110'!$A:$BP,펀드현황!P$2,0) -> 59.0336 | T19: =C19 -> 05C72 | V19: =IFERROR( ( SUMIFS(설정해지!$G:$G, 설정해지!$B:$B,펀드현황!$C19,설정해지!$F:$F,"KRW")-SUMIFS(설정해지!$H:$H, 설정해지!$B:$B,펀드현황!$C19,설정해지!$F:$F,"KRW") ) /100000000,"") -> -0.13030738 | W19: =IFERROR( ( SUMIFS(설정해지!$I:$I, 설정해지!$B:$B,펀드현황!$C19,설정해지!$F:$F,"KRW")-SUMIFS(설정해지!$J:$J, 설정해지!$B:$B,펀드현황!$C19,설정해지!$F:$F,"KRW") ) /100000000,"") -> 1.8456872 | X19: =IFERROR( ( SUMIFS(설정해지!$K:$K, 설정해지!$B:$B,펀드현황!$C19,설정해지!$F:$F,"KRW")-SUMIFS(설정해지!$L:$L, 설정해지!$B:$B,펀드현황!$C19,설정해지!$F:$F,"KRW") ) /100000000,"") -> -7.1000374 | Z19: =IFERROR( ( SUMIFS(자금총괄!$G:$G, 자금총괄!$B:$B,펀드현황!$C19,자금총괄!$F:$F,$AB$2) ) /100000000,"") -> 62.801468 | AA19: =Z19/F19 -> 0.030647005 | AB19: =IFERROR( ( SUMIFS(자금총괄!$I:$I, 자금총괄!$B:$B,펀드현황!$C19,자금총괄!$F:$F,$AB$2) ) /100000000,"") -> 64.647155 | AC19: =IFERROR( ( SUMIFS(자금총괄!$K:$K, 자금총괄!$B:$B,펀드현황!$C19,자금총괄!$F:$F,$AB$2) ) /100000000,"") -> 57.547118 | AD19: =IFERROR( ( SUMIFS(자금총괄!$M:$M, 자금총괄!$B:$B,펀드현황!$C19,자금총괄!$F:$F,$AB$2) ) /100000000,"") -> 55.979451 | AE19: =IFERROR( ( SUMIFS(자금총괄!$O:$O, 자금총괄!$B:$B,펀드현황!$C19,자금총괄!$F:$F,$AB$2) ) /100000000,"") -> 54.357342 | AF19: =IFERROR( ( SUMIFS(자금총괄!$Q:$Q, 자금총괄!$B:$B,펀드현황!$C19,자금총괄!$F:$F,$AB$2) ) /100000000,"") -> 400.71756 | AH19: =IFERROR( ( SUMIFS(자금총괄!$G:$G, 자금총괄!$B:$B,펀드현황!$C19,자금총괄!$F:$F,$AI$2)/10000 ),"") -> 6.647696 | AI19: =IFERROR( ( SUMIFS(자금총괄!$I:$I, 자금총괄!$B:$B,펀드현황!$C19,자금총괄!$F:$F,$AI$2)/10000 ),"") -> 6.647696 | AJ19: =IFERROR((SUMIFS(자금총괄!$K:$K,자금총괄!$B:$B,펀드현황!$C19,자금총괄!$F:$F,$AI$2)/10000),"") -> 6.647696 | AK19: =IFERROR((SUMIFS(자금총괄!$M:$M,자금총괄!$B:$B,펀드현황!$C19,자금총괄!$F:$F,$AI$2)/10000),"") -> 6.647696 | AL19: =IFERROR( ( SUMIFS(자금총괄!$O:$O, 자금총괄!$B:$B,펀드현황!$C19,자금총괄!$F:$F,$AI$2) /10000 ),"") -> 6.647696 | AM19: =IFERROR( ( SUMIFS(자금총괄!$Q:$Q, 자금총괄!$B:$B,펀드현황!$C19,자금총괄!$F:$F,$AI$2) /10000 ),"") -> -2673.3523
C20: 05C86 | D20: =VLOOKUP(C20,'MOS4110'!$A:$B,2,0) -> 한국투자TDF알아서2045증권투자신탁(주식혼합-재간접형)(모) | E20: =AVERAGEIFS(#REF!,#REF!,펀드현황!$C20)/100000000 -> #REF! | F20: =IFERROR(VLOOKUP($T20,자금총괄!$B:$E,4,0)/100000000,"") -> 2901.8146 | G20: =VLOOKUP($C20,'MOS4110'!$A:$BP,펀드현황!G$2,0) -> 42796 | H20: =VLOOKUP($C20,'MOS4110'!$A:$BP,펀드현황!H$2,0) -> 1582.38 | I20: =VLOOKUP($C20,'MOS4110'!$A:$BP,펀드현황!I$2,0) -> 3.1317 | J20: =VLOOKUP($C20,'MOS4110'!$A:$BP,펀드현황!J$2,0) -> 8.7913 | K20: =VLOOKUP($C20,'MOS4110'!$A:$BP,펀드현황!K$2,0) -> 9.9394 | L20: =VLOOKUP($C20,'MOS4110'!$A:$BP,펀드현황!L$2,0) -> 14.7796 | M20: =VLOOKUP($C20,'MOS4110'!$A:$BP,펀드현황!M$2,0) -> 9.8603 | N20: =VLOOKUP($C20,'MOS4110'!$A:$BP,펀드현황!N$2,0) -> 4.8544 | ... P20: =VLOOKUP($C20,'MOS4110'!$A:$BP,펀드현황!P$2,0) -> 60.5712 | T20: =C20 -> 05C86 | V20: =IFERROR( ( SUMIFS(설정해지!$G:$G, 설정해지!$B:$B,펀드현황!$C20,설정해지!$F:$F,"KRW")-SUMIFS(설정해지!$H:$H, 설정해지!$B:$B,펀드현황!$C20,설정해지!$F:$F,"KRW") ) /100000000,"") -> 5.6872295 | W20: =IFERROR( ( SUMIFS(설정해지!$I:$I, 설정해지!$B:$B,펀드현황!$C20,설정해지!$F:$F,"KRW")-SUMIFS(설정해지!$J:$J, 설정해지!$B:$B,펀드현황!$C20,설정해지!$F:$F,"KRW") ) /100000000,"") -> 3.8775186 | X20: =IFERROR( ( SUMIFS(설정해지!$K:$K, 설정해지!$B:$B,펀드현황!$C20,설정해지!$F:$F,"KRW")-SUMIFS(설정해지!$L:$L, 설정해지!$B:$B,펀드현황!$C20,설정해지!$F:$F,"KRW") ) /100000000,"") -> -9.7334857 | Z20: =IFERROR( ( SUMIFS(자금총괄!$G:$G, 자금총괄!$B:$B,펀드현황!$C20,자금총괄!$F:$F,$AB$2) ) /100000000,"") -> 139.73402 | AA20: =Z20/F20 -> 0.048154012 | AB20: =IFERROR( ( SUMIFS(자금총괄!$I:$I, 자금총괄!$B:$B,펀드현황!$C20,자금총괄!$F:$F,$AB$2) ) /100000000,"") -> 143.61153 | AC20: =IFERROR( ( SUMIFS(자금총괄!$K:$K, 자금총괄!$B:$B,펀드현황!$C20,자금총괄!$F:$F,$AB$2) ) /100000000,"") -> 133.87805 | AD20: =IFERROR( ( SUMIFS(자금총괄!$M:$M, 자금총괄!$B:$B,펀드현황!$C20,자금총괄!$F:$F,$AB$2) ) /100000000,"") -> 130.65804 | AE20: =IFERROR( ( SUMIFS(자금총괄!$O:$O, 자금총괄!$B:$B,펀드현황!$C20,자금총괄!$F:$F,$AB$2) ) /100000000,"") -> 125.85006 | AF20: =IFERROR( ( SUMIFS(자금총괄!$Q:$Q, 자금총괄!$B:$B,펀드현황!$C20,자금총괄!$F:$F,$AB$2) ) /100000000,"") -> 587.70404 | AH20: =IFERROR( ( SUMIFS(자금총괄!$G:$G, 자금총괄!$B:$B,펀드현황!$C20,자금총괄!$F:$F,$AI$2)/10000 ),"") -> 81.07425 | AI20: =IFERROR( ( SUMIFS(자금총괄!$I:$I, 자금총괄!$B:$B,펀드현황!$C20,자금총괄!$F:$F,$AI$2)/10000 ),"") -> 81.07425 | AJ20: =IFERROR((SUMIFS(자금총괄!$K:$K,자금총괄!$B:$B,펀드현황!$C20,자금총괄!$F:$F,$AI$2)/10000),"") -> 81.07425 | AK20: =IFERROR((SUMIFS(자금총괄!$M:$M,자금총괄!$B:$B,펀드현황!$C20,자금총괄!$F:$F,$AI$2)/10000),"") -> 81.07425 | AL20: =IFERROR( ( SUMIFS(자금총괄!$O:$O, 자금총괄!$B:$B,펀드현황!$C20,자금총괄!$F:$F,$AI$2) /10000 ),"") -> 81.07425 | AM20: =IFERROR( ( SUMIFS(자금총괄!$Q:$Q, 자금총괄!$B:$B,펀드현황!$C20,자금총괄!$F:$F,$AI$2) /10000 ),"") -> -3500.9257
